Workbook
Name Adj_closing_price: OFFSET(#REF!,1,0,COUNT(#REF!),1)
Name cmdOK2_click: [1]!cmdOK2_click
Name Date: OFFSET(#REF!,1,0,COUNT(#REF!),1)
Name PAGE1: [2]GROMM!#REF!
Name PAGE2: #REF!
Name PE_band_1: OFFSET(#REF!,1,0,COUNT(#REF!),1)
Name PE_band_2: OFFSET(#REF!,1,0,COUNT(#REF!),1)
Name PE_band_3: OFFSET(#REF!,1,0,COUNT(#REF!),1)
Name PE_band_4: OFFSET(#REF!,1,0,COUNT(#REF!),1)
Name PE_band_5: OFFSET(#REF!,1,0,COUNT(#REF!),1)
Name Price: [1]Template!#REF!
Name Print_Area_MI: #REF!
Name startCompany: [1]Sheet1!#REF!
Name Units: #REF!

Sheet Dashboard
A1: [Britannia LTD.]
A2: Ratio Snapshot
A3: (In INR Crores, unless otherwise stated)
A5: COMPANY DETAILS | H5: Expectations in 5 Years: 2021 - 2025 | O5: Cash vs PAT 2021 - 2025
A6: Industry | B6: [FMCG]
A7: Sector | B7: Packaged Foods
A8: Current Market Price | B8: 3270
A9: Market Capitalization | B9: =B8*'Income Statement'!D46 -> 78741.6
A10: Year end | B10: [2021]
A12: COMPANY DESCRIPTION
A13: Britannia is among the most trusted food brands, and manufactures India’s favorite brands like Good Day, Tiger, NutriChoice, Milk Bikis and Marie Gold which are household names in India. Britannia’s product portfolio includes Biscuits, Bread, Cakes, Rusk, and Dairy products including Cheese, Beverages, Milk and Yoghurt.
A24: Financial Year | B24: =Assumptions!E5 -> FY2022 E | C24: =Assumptions!F5 -> FY2023 E | D24: =Assumptions!G5 -> FY2024 E | E24: =Assumptions!H5 -> FY2025 E | F24: =Assumptions!I5 -> FY2026 E | H24: DEBT and Market Cap
A26: Revenue | B26: ='Income Statement'!E7 -> 14318.24 | C26: ='Income Statement'!F7 -> 15606.882 | D26: ='Income Statement'!G7 -> 17011.501 | E26: ='Income Statement'!H7 -> 18542.536 | F26: ='Income Statement'!I7 -> 20211.364
A27: COGS | B27: ='Income Statement'!E13 -> -8454.1093 | C27: ='Income Statement'!F13 -> -9198.8653 | D27: ='Income Statement'!G13 -> -9982.3272 | E27: ='Income Statement'!H13 -> -10919.408 | F27: ='Income Statement'!I13 -> -11891.652
A28: Gross Profit | B28: ='Income Statement'!E14 -> 5864.1307 | C28: ='Income Statement'!F14 -> 6408.0163 | D28: ='Income Statement'!G14 -> 7029.1737 | E28: ='Income Statement'!H14 -> 7623.1276 | F28: ='Income Statement'!I14 -> 8319.7125
A29: Gross Margin (%) | B29: ='Income Statement'!E63 -> 0.40955667 | C29: ='Income Statement'!F63 -> 0.41058916 | D29: ='Income Statement'!G63 -> 0.41320127 | E29: ='Income Statement'!H63 -> 0.4111157 | F29: ='Income Statement'!I63 -> 0.41163537
A31: Net Profit / EBITDA | B31: ='Income Statement'!E23 -> 2419.2442 | C31: ='Income Statement'!F23 -> 2699.433 | D31: ='Income Statement'!G23 -> 3022.4029 | E31: ='Income Statement'!H23 -> 3211.5357 | F31: ='Income Statement'!I23 -> 3529.1116
A32: Net Margin (%) | B32: ='Income Statement'!E83 -> 0.12451785 | C32: ='Income Statement'!F83 -> 0.12739417 | D32: ='Income Statement'!G83 -> 0.12959685 | E32: ='Income Statement'!H83 -> 0.12584282 | F32: ='Income Statement'!I83 -> 0.1263738
A33: Tax Expenses | B33: =SUM('Income Statement'!E32:E34) -> -607.27005 | C33: =SUM('Income Statement'!F32:F34) -> -677.2146 | D33: =SUM('Income Statement'!G32:G34) -> -763.67629 | E33: =SUM('Income Statement'!H32:H34) -> -799.28575 | F33: =SUM('Income Statement'!I32:I34) -> -876.53716
A34: Profit After Tax | B34: ='Income Statement'!E41 -> 1782.8765 | C34: ='Income Statement'!F41 -> 1988.2258 | D34: ='Income Statement'!G41 -> 2204.637 | E34: ='Income Statement'!H41 -> 2333.445 | F34: ='Income Statement'!I41 -> 2554.187
A35: Net Profit (%) | B35: =Dashboard!B32 -> 0.12451785 | C35: =Dashboard!C32 -> 0.12739417 | D35: =Dashboard!D32 -> 0.12959685 | E35: =Dashboard!E32 -> 0.12584282 | F35: =Dashboard!F32 -> 0.1263738
A36: Cash | B36: ='Balance Sheet'!E8 -> 1480.3768 | C36: ='Balance Sheet'!F8 -> 2931.1837 | D36: ='Balance Sheet'!G8 -> 4469.8027 | E36: ='Balance Sheet'!H8 -> 6149.6658 | F36: ='Balance Sheet'!I8 -> 7972.567
A38: ROA | B38: ='Company Overview'!E41 -> 8.9117246 | C38: ='Company Overview'!F41 -> 9.7660565 | D38: ='Company Overview'!G41 -> 10.688108 | E38: ='Company Overview'!H41 -> 11.746376 | F38: ='Company Overview'!I41 -> 12.85429
A39: Financial Leverage | B39: ='Company Overview'!B47 -> 0.02437744 | C39: ='Company Overview'!C47 -> 0.18890476 | D39: ='Company Overview'!D47 -> 0.22614676 | E39: ='Company Overview'!E47 -> 0.16835872 | F39: ='Company Overview'!F47 -> 0.131022
A40: Net Margin (%) | B40: =B32 -> 0.12451785 | C40: =C32 -> 0.12739417 | D40: =D32 -> 0.12959685 | E40: =E32 -> 0.12584282 | F40: =F32 -> 0.1263738
A41: ROE | B41: ='Company Overview'!E42 -> 0.37033819 | C41: ='Company Overview'!F42 -> 0.32140419 | D41: ='Company Overview'!G42 -> 0.28604679 | E41: ='Company Overview'!H42 -> 0.25044119 | F41: ='Company Overview'!I42 -> 0.23052799
A43: Enterprise Value | B43: =B24 -> FY2022 E | C43: =C24 -> FY2023 E | D43: =D24 -> FY2024 E | E43: =E24 -> FY2025 E | F43: =F24 -> FY2026 E
A44: Net Debt
A45: Market Capitalisation
A46: Cash and Cash Equivalent
A47: Enterprise Value (EV)

Sheet Company Overview
A1: =Dashboard!A1 -> [Britannia LTD.]
A2: Ratio Snapshot
A3: (In INR Crores, unless otherwise stated)
A6: HIGHLIGHTS FROM INCOME STATEMENT | B6: =Assumptions!B5 -> FY2019 A | C6: =Assumptions!C5 -> FY2020 A | D6: =Assumptions!D5 -> FY2021 A | E6: =Assumptions!E5 -> FY2022 E | F6: =Assumptions!F5 -> FY2023 E | G6: =Assumptions!G5 -> FY2024 E | H6: =Assumptions!H5 -> FY2025 E | I6: =Assumptions!I5 -> FY2026 E | ... L6: =Assumptions!L5 -> FY2029 E
A7: Revenue | B7: ='Income Statement'!B7 -> 11054 | C7: ='Income Statement'!C7 -> 11599 | D7: ='Income Statement'!D7 -> 13136 | E7: ='Income Statement'!E7 -> 14318.24 | F7: ='Income Statement'!F7 -> 15606.882 | G7: ='Income Statement'!G7 -> 17011.501 | H7: ='Income Statement'!H7 -> 18542.536 | I7: ='Income Statement'!I7 -> 20211.364 | ... L7: ='Income Statement'!L7 -> 26174.303
A8: EBITDA | B8: ='Income Statement'!B23 -> 1735 | C8: ='Income Statement'!C23 -> 1842.53 | D8: ='Income Statement'!D23 -> 2510 | E8: ='Income Statement'!E23 -> 2419.2442 | F8: ='Income Statement'!F23 -> 2699.433 | G8: ='Income Statement'!G23 -> 3022.4029 | H8: ='Income Statement'!H23 -> 3211.5357 | I8: ='Income Statement'!I23 -> 3529.1116 | ... L8: ='Income Statement'!L23 -> 4572.5781
A9: EBIT | B9: ='Income Statement'!B25 -> 1573.12 | C9: ='Income Statement'!C25 -> 1657.72 | D9: ='Income Statement'!D25 -> 2312.15 | E9: ='Income Statement'!E25 -> 2194.27 | F9: ='Income Statement'!F25 -> 2463.118 | G9: ='Income Statement'!G25 -> 2767.8803 | H9: ='Income Statement'!H25 -> 2933.1867 | I9: ='Income Statement'!I25 -> 3229.9577 | ... L9: ='Income Statement'!L25 -> 4192.1964
A10: PBT | B10: ='Income Statement'!B31 -> 1769.51 | C10: ='Income Statement'!C31 -> 1843.65 | D10: ='Income Statement'!D31 -> 2514.45 | E10: ='Income Statement'!E31 -> 2390.1465 | F10: ='Income Statement'!F31 -> 2665.4404 | G10: ='Income Statement'!G31 -> 2968.3133 | H10: ='Income Statement'!H31 -> 3132.7307 | I10: ='Income Statement'!I31 -> 3430.7242 | ... L10: ='Income Statement'!L31 -> 4392.5966
A11: PAT | B11: ='Income Statement'!B35 -> 1157.04 | C11: ='Income Statement'!C35 -> 1392.95 | D11: ='Income Statement'!D35 -> 1851.43 | E11: ='Income Statement'!E35 -> 1782.8765 | F11: ='Income Statement'!F35 -> 1988.2258 | G11: ='Income Statement'!G35 -> 2204.637 | H11: ='Income Statement'!H35 -> 2333.445 | I11: ='Income Statement'!I35 -> 2554.187 | ... L11: ='Income Statement'!L35 -> 3269.5517
A13: HIGHLIGHTS FROM BALANCE SHEET | B13: =B6 -> FY2019 A | C13: =C6 -> FY2020 A | D13: =D6 -> FY2021 A | E13: =E6 -> FY2022 E | F13: =F6 -> FY2023 E | G13: =G6 -> FY2024 E | H13: =H6 -> FY2025 E | I13: =I6 -> FY2026 E | ... L13: =L6 -> FY2029 E
A14: Fixed Assets | B14: ='Balance Sheet'!B20 -> 1535.58 | C14: ='Balance Sheet'!C20 -> 1716.37 | D14: ='Balance Sheet'!D20 -> 1634.3 | E14: ='Balance Sheet'!E20 -> 1606.6744 | F14: ='Balance Sheet'!F20 -> 1598.0741 | G14: ='Balance Sheet'!G20 -> 1591.6288 | H14: ='Balance Sheet'!H20 -> 1578.5751 | I14: ='Balance Sheet'!I20 -> 1572.3439 | ... L14: ='Balance Sheet'!L20 -> 1559.715
A15: Cash & Cash Equivalents | B15: ='Balance Sheet'!B8 -> 60.32 | C15: ='Balance Sheet'!C8 -> 81.23 | D15: ='Balance Sheet'!D8 -> 142.74 | E15: ='Balance Sheet'!E8 -> 1480.3768 | F15: ='Balance Sheet'!F8 -> 2931.1837 | G15: ='Balance Sheet'!G8 -> 4469.8027 | H15: ='Balance Sheet'!H8 -> 6149.6658 | I15: ='Balance Sheet'!I8 -> 7972.567 | ... L15: ='Balance Sheet'!L8 -> 14405.129
A16: Working Capital | B16: ='Balance Sheet'!B18-'Balance Sheet'!B43 -> 1674.93 | C16: ='Balance Sheet'!C18-'Balance Sheet'!C43 -> 1109.67 | D16: ='Balance Sheet'!D18-'Balance Sheet'!D43 -> 805.41 | E16: ='Balance Sheet'!E18-'Balance Sheet'!E43 -> 2050.9429 | F16: ='Balance Sheet'!F18-'Balance Sheet'!F43 -> 3418.2579 | G16: ='Balance Sheet'!G18-'Balance Sheet'!G43 -> 4931.883 | H16: ='Balance Sheet'!H18-'Balance Sheet'!H43 -> 6539.9787 | I16: ='Balance Sheet'!I18-'Balance Sheet'!I43 -> 8291.9186 | ... L16: ='Balance Sheet'!L18-'Balance Sheet'!L43 -> 14491.418
A17: Long Term Debts and Borrowing | B17: ='Balance Sheet'!B45 -> 61.92 | C17: ='Balance Sheet'!C45 -> 766.06 | D17: ='Balance Sheet'!D45 -> 747.75 | E17: ='Balance Sheet'!E45 -> 747.75 | F17: ='Balance Sheet'!F45 -> 747.75 | G17: ='Balance Sheet'!G45 -> 747.75 | H17: ='Balance Sheet'!H45 -> 747.75 | I17: ='Balance Sheet'!I45 -> 747.75 | ... L17: ='Balance Sheet'!L45 -> 747.75
A18: Equity | B18: ='Balance Sheet'!B55 -> 24.03 | C18: ='Balance Sheet'!C55 -> 24.05 | D18: ='Balance Sheet'!D55 -> 24.09 | E18: ='Balance Sheet'!E55 -> 24.09 | F18: ='Balance Sheet'!F55 -> 24.09 | G18: ='Balance Sheet'!G55 -> 24.09 | H18: ='Balance Sheet'!H55 -> 24.09 | I18: ='Balance Sheet'!I55 -> 24.09 | ... L18: ='Balance Sheet'!L55 -> 24.09
A19: Share holders fund | B19: ='Balance Sheet'!B56 -> 4229.22 | C19: ='Balance Sheet'!C56 -> 4378.78 | D19: ='Balance Sheet'!D56 -> 3523.57 | E19: ='Balance Sheet'!E56 -> 4753.7548 | F19: ='Balance Sheet'!F56 -> 6125.6305 | G19: ='Balance Sheet'!G56 -> 7646.8301 | H19: ='Balance Sheet'!H56 -> 9256.9071 | I19: ='Balance Sheet'!I56 -> 11019.296 | ... L19: ='Balance Sheet'!L56 -> 17265.323
A21: GROWTH | B21: =B13 -> FY2019 A | C21: =C13 -> FY2020 A | D21: =D13 -> FY2021 A | E21: =E13 -> FY2022 E | F21: =F13 -> FY2023 E | G21: =G13 -> FY2024 E | H21: =H13 -> FY2025 E | I21: =I13 -> FY2026 E | ... L21: =L13 -> FY2029 E
A22: Revenue Growth y-o-y | C22: =Assumptions!C7 -> 0.04930342 | D22: =Assumptions!D7 -> 0.13251142 | E22: =Assumptions!E7 -> 0.09 | F22: =Assumptions!F7 -> 0.09 | G22: =Assumptions!G7 -> 0.09 | H22: =Assumptions!H7 -> 0.09 | I22: =Assumptions!I7 -> 0.09 | J22: =Assumptions!J7 -> 0.09 | ... L22: =Assumptions!L7 -> 0.09
A23: EBIT Growth y-o-y | C23: =('Income Statement'!C25/'Income Statement'!B25)-1 -> 0.053778478 | D23: =('Income Statement'!D25/'Income Statement'!C25)-1 -> 0.39477716 | E23: =('Income Statement'!E25/'Income Statement'!D25)-1 -> -0.050982862 | F23: =('Income Statement'!F25/'Income Statement'!E25)-1 -> 0.12252274 | G23: =('Income Statement'!G25/'Income Statement'!F25)-1 -> 0.1237303 | H23: =('Income Statement'!H25/'Income Statement'!G25)-1 -> 0.059723117 | I23: =('Income Statement'!I25/'Income Statement'!H25)-1 -> 0.10117698 | J23: =('Income Statement'!J25/'Income Statement'!I25)-1 -> 0.094383433 | ... L23: =('Income Statement'!L25/'Income Statement'!K25)-1 -> 0.093288089
A24: PAT growth y-o-y | C24: =('Income Statement'!C35/'Income Statement'!B35)-1 -> 0.20389096 | D24: =('Income Statement'!D35/'Income Statement'!C35)-1 -> 0.32914319 | E24: =('Income Statement'!E35/'Income Statement'!D35)-1 -> -0.03702734 | F24: =('Income Statement'!F35/'Income Statement'!E35)-1 -> 0.11517865 | G24: =('Income Statement'!G35/'Income Statement'!F35)-1 -> 0.10884639 | H24: =('Income Statement'!H35/'Income Statement'!G35)-1 -> 0.058425934 | I24: =('Income Statement'!I35/'Income Statement'!H35)-1 -> 0.094599205 | J24: =('Income Statement'!J35/'Income Statement'!I35)-1 -> 0.088014834 | ... L24: =('Income Statement'!L35/'Income Statement'!K35)-1 -> 0.088519699
A26: MARGINS | B26: =B6 -> FY2019 A | C26: =C6 -> FY2020 A | D26: =D6 -> FY2021 A | E26: =E6 -> FY2022 E | F26: =F6 -> FY2023 E | G26: =G6 -> FY2024 E | H26: =H6 -> FY2025 E | I26: =I6 -> FY2026 E | ... L26: =L6 -> FY2029 E
A27: Gross Profit Margin (%) | B27: ='Income Statement'!B63 -> 0.4064592 | C27: ='Income Statement'!C63 -> 0.40275282 | D27: ='Income Statement'!D63 -> 0.41945798 | E27: ='Income Statement'!E63 -> 0.40955667 | F27: ='Income Statement'!F63 -> 0.41058916 | G27: ='Income Statement'!G63 -> 0.41320127 | H27: ='Income Statement'!H63 -> 0.4111157 | I27: ='Income Statement'!I63 -> 0.41163537 | ... L27: ='Income Statement'!L63 -> 0.41173263
A28: EBITDA Margin (%) | B28: ='Income Statement'!B72 -> 0.15695676 | C28: ='Income Statement'!C72 -> 0.15885249 | D28: ='Income Statement'!D72 -> 0.19107795 | E28: ='Income Statement'!E72 -> 0.1689624 | F28: ='Income Statement'!F72 -> 0.17296428 | G28: ='Income Statement'!G72 -> 0.17766821 | H28: ='Income Statement'!H72 -> 0.1731983 | I28: ='Income Statement'!I72 -> 0.17461026 | ... L28: ='Income Statement'!L72 -> 0.17469723
A29: EBIT Margin (%) | B29: ='Income Statement'!B74 -> 0.14231229 | C29: ='Income Statement'!C74 -> 0.14291922 | D29: ='Income Statement'!D74 -> 0.17601629 | E29: ='Income Statement'!E74 -> 0.15324998 | F29: ='Income Statement'!F74 -> 0.15782256 | G29: ='Income Statement'!G74 -> 0.16270641 | H29: ='Income Statement'!H74 -> 0.15818692 | I29: ='Income Statement'!I74 -> 0.15980899 | ... L29: ='Income Statement'!L74 -> 0.16016459
A30: Pre-Tax Margin (%) | B30: ='Income Statement'!B79 -> 0.1600787 | C30: ='Income Statement'!C79 -> 0.15894905 | D30: ='Income Statement'!D79 -> 0.19141672 | E30: ='Income Statement'!E79 -> 0.16693019 | F30: ='Income Statement'!F79 -> 0.17078622 | G30: ='Income Statement'!G79 -> 0.17448862 | H30: ='Income Statement'!H79 -> 0.16894834 | I30: ='Income Statement'!I79 -> 0.16974233 | ... L30: ='Income Statement'!L79 -> 0.16782096
A31: PAT Margin (%) | B31: ='Income Statement'!B83 -> 0.10467161 | C31: ='Income Statement'!C83 -> 0.12009225 | D31: ='Income Statement'!D83 -> 0.14094321 | E31: ='Income Statement'!E83 -> 0.12451785 | F31: ='Income Statement'!F83 -> 0.12739417 | G31: ='Income Statement'!G83 -> 0.12959685 | H31: ='Income Statement'!H83 -> 0.12584282 | I31: ='Income Statement'!I83 -> 0.1263738 | ... L31: ='Income Statement'!L83 -> 0.12491457
A33: EXPENDITURE RATIOS | B33: =B26 -> FY2019 A | C33: =C26 -> FY2020 A | D33: =D26 -> FY2021 A | E33: =E26 -> FY2022 E | F33: =F26 -> FY2023 E | G33: =G26 -> FY2024 E | H33: =H26 -> FY2025 E | I33: =I26 -> FY2026 E | ... L33: =L26 -> FY2029 E
A34: Cost of Goods Sold as % of Revenue | B34: =ABS('Income Statement'!B62) -> 0.5935408 | C34: =ABS('Income Statement'!C62) -> 0.59724718 | D34: =ABS('Income Statement'!D62) -> 0.58054202 | E34: =ABS('Income Statement'!E62) -> 0.59044333 | F34: =ABS('Income Statement'!F62) -> 0.58941084 | G34: =ABS('Income Statement'!G62) -> 0.58679873 | H34: =ABS('Income Statement'!H62) -> 0.5888843 | I34: =ABS('Income Statement'!I62) -> 0.58836463 | ... L34: =ABS('Income Statement'!L62) -> 0.58826737
A35: Employee Expenses as % of Revenue | B35: ='Income Statement'!B67 -> 0.04640854 | C35: ='Income Statement'!C67 -> 0.043796879 | D35: ='Income Statement'!D67 -> 0.043316078 | E35: ='Income Statement'!E67 -> 0.044507166 | F35: ='Income Statement'!F67 -> 0.043873374 | G35: ='Income Statement'!G67 -> 0.043898873 | H35: ='Income Statement'!H67 -> 0.044093137 | I35: ='Income Statement'!I67 -> 0.043955128 | ... L35: ='Income Statement'!L67 -> 0.043982574
A36: Advertisement Expenses as % of Revenue | B36: ='Income Statement'!B66 -> 0.04532296 | C36: ='Income Statement'!C66 -> 0.040951806 | D36: ='Income Statement'!D66 -> 0.034409257 | E36: ='Income Statement'!E66 -> 0.040228008 | F36: ='Income Statement'!F66 -> 0.03852969 | G36: ='Income Statement'!G66 -> 0.037722318 | H36: ='Income Statement'!H66 -> 0.038826672 | I36: ='Income Statement'!I66 -> 0.03835956 | ... L36: ='Income Statement'!L66 -> 0.038386257
A39: RETURNS | B39: =B6 -> FY2019 A | C39: =C6 -> FY2020 A | D39: =D6 -> FY2021 A | E39: =E6 -> FY2022 E | F39: =F6 -> FY2023 E | G39: =G6 -> FY2024 E | H39: =H6 -> FY2025 E | I39: =I6 -> FY2026 E | ... L39: =L6 -> FY2029 E
A40: Return on Avg Cap Employed (%) | B40: ='Income Statement'!B25/('Balance Sheet'!B33-'Balance Sheet'!B43) -> 0.35830822 | C40: ='Income Statement'!C25/('Balance Sheet'!C33-'Balance Sheet'!C43) -> 0.31414478 | D40: ='Income Statement'!D25/('Balance Sheet'!D33-'Balance Sheet'!D43) -> 0.52614512 | E40: ='Income Statement'!E25/('Balance Sheet'!E33-'Balance Sheet'!E43) -> 0.39020241 | F40: ='Income Statement'!F25/('Balance Sheet'!F33-'Balance Sheet'!F43) -> 0.35211089 | G40: ='Income Statement'!G25/('Balance Sheet'!G33-'Balance Sheet'!G43) -> 0.32500247 | H40: ='Income Statement'!H25/('Balance Sheet'!H33-'Balance Sheet'!H43) -> 0.28965262 | I40: ='Income Statement'!I25/('Balance Sheet'!I33-'Balance Sheet'!I43) -> 0.27167715 | ... L40: ='Income Statement'!L25/('Balance Sheet'!L33-'Balance Sheet'!L43) -> 0.23116627
A41: Return on Assets | B41: ='Income Statement'!B7/('Balance Sheet'!B20) -> 7.1985829 | C41: ='Income Statement'!C7/('Balance Sheet'!C20) -> 6.7578669 | D41: ='Income Statement'!D7/('Balance Sheet'!D20) -> 8.037692 | E41: ='Income Statement'!E7/('Balance Sheet'!E20) -> 8.9117246 | F41: ='Income Statement'!F7/('Balance Sheet'!F20) -> 9.7660565 | G41: ='Income Statement'!G7/('Balance Sheet'!G20) -> 10.688108 | H41: ='Income Statement'!H7/('Balance Sheet'!H20) -> 11.746376 | I41: ='Income Statement'!I7/('Balance Sheet'!I20) -> 12.85429 | ... L41: ='Income Statement'!L7/('Balance Sheet'!L20) -> 16.781466
A42: Return On Equity (%) | B42: ='Income Statement'!B41/'Balance Sheet'!B59 -> 0.27085837 | C42: ='Income Statement'!C41/'Balance Sheet'!C59 -> 0.31498846 | D42: ='Income Statement'!D41/'Balance Sheet'!D59 -> 0.5161635 | E42: ='Income Statement'!E41/'Balance Sheet'!E59 -> 0.37033819 | F42: ='Income Statement'!F41/'Balance Sheet'!F59 -> 0.32140419 | G42: ='Income Statement'!G41/'Balance Sheet'!G59 -> 0.28604679 | H42: ='Income Statement'!H41/'Balance Sheet'!H59 -> 0.25044119 | I42: ='Income Statement'!I41/'Balance Sheet'!I59 -> 0.23052799 | ... L42: ='Income Statement'!L41/'Balance Sheet'!L59 -> 0.18871051
A44: DuPONT ANALYSIS | B44: =B6 -> FY2019 A | C44: =C6 -> FY2020 A | D44: =D6 -> FY2021 A | E44: =E6 -> FY2022 E | F44: =F6 -> FY2023 E | G44: =G6 -> FY2024 E | H44: =H6 -> FY2025 E | I44: =I6 -> FY2026 E | ... L44: =L6 -> FY2029 E
A45: PAT Margin (%) | B45: ='Income Statement'!B83 -> 0.10467161 | C45: ='Income Statement'!C83 -> 0.12009225 | D45: ='Income Statement'!D83 -> 0.14094321 | E45: ='Income Statement'!E83 -> 0.12451785 | F45: ='Income Statement'!F83 -> 0.12739417 | G45: ='Income Statement'!G83 -> 0.12959685 | H45: ='Income Statement'!H83 -> 0.12584282 | I45: ='Income Statement'!I83 -> 0.1263738 | ... L45: ='Income Statement'!L83 -> 0.12491457
A46: Asset Turnover (x) | B46: =B41 -> 7.1985829 | C46: =C41 -> 6.7578669 | D46: =D41 -> 8.037692 | E46: =E41 -> 8.9117246 | F46: =F41 -> 9.7660565 | G46: =G41 -> 10.688108 | H46: =H41 -> 11.746376 | I46: =I41 -> 12.85429 | ... L46: =L41 -> 16.781466
A47: Financial Leverage | B47: ='Balance Sheet'!B51/'Balance Sheet'!B59 -> 0.02437744 | C47: ='Balance Sheet'!C51/'Balance Sheet'!C59 -> 0.18890476 | D47: ='Balance Sheet'!D51/'Balance Sheet'!D59 -> 0.22614676 | E47: ='Balance Sheet'!E51/'Balance Sheet'!E59 -> 0.16835872 | F47: ='Balance Sheet'!F51/'Balance Sheet'!F59 -> 0.131022 | G47: ='Balance Sheet'!G51/'Balance Sheet'!G59 -> 0.10516189 | H47: ='Balance Sheet'!H51/'Balance Sheet'!H59 -> 0.086989447 | I47: ='Balance Sheet'!I51/'Balance Sheet'!I59 -> 0.07315253 | ... L47: ='Balance Sheet'!L51/'Balance Sheet'!L59 -> 0.046780651
A48: Return On Equity (%) | B48: =B42 -> 0.27085837 | C48: =C42 -> 0.31498846 | D48: =D42 -> 0.5161635 | E48: =E42 -> 0.37033819 | F48: =F42 -> 0.32140419 | G48: =G42 -> 0.28604679 | H48: =H42 -> 0.25044119 | I48: =I42 -> 0.23052799 | ... L48: =L42 -> 0.18871051
A50: LIQUIDITY | B50: =B6 -> FY2019 A | C50: =C6 -> FY2020 A | D50: =D6 -> FY2021 A | E50: =E6 -> FY2022 E | F50: =F6 -> FY2023 E | G50: =G6 -> FY2024 E | H50: =H6 -> FY2025 E | I50: =I6 -> FY2026 E | ... L50: =L6 -> FY2029 E
...

Sheet Assumptions
A1: =Dashboard!A1 -> [Britannia LTD.]
A2: Assumptions
A5: Particular | B5: FY2019 A | C5: FY2020 A | D5: FY2021 A | E5: FY2022 E | F5: FY2023 E | G5: FY2024 E | H5: FY2025 E | I5: FY2026 E | J5: FY2027 E | K5: FY2028 E | L5: FY2029 E
A6: Income Statement
A7: Revenue Growth | C7: =('Income Statement'!C7/'Income Statement'!B7)-1 -> 0.04930342 | D7: =('Income Statement'!D7/'Income Statement'!C7)-1 -> 0.13251142 | E7: 0.09 | F7: 0.09 | G7: 0.09 | H7: 0.09 | I7: 0.09 | J7: 0.09 | K7: 0.09 | L7: 0.09
A8: COGS | B8: =ABS('Income Statement'!B13/'Income Statement'!B7) -> 0.5935408 | C8: =ABS('Income Statement'!C13/'Income Statement'!C7) -> 0.59724718 | D8: =ABS('Income Statement'!D13/'Income Statement'!D7) -> 0.58054202 | E8: =AVERAGE(B8:D8) -> 0.59044333 | F8: =AVERAGE(C8:E8) -> 0.58941084 | G8: =AVERAGE(D8:F8) -> 0.58679873 | H8: =AVERAGE(E8:G8) -> 0.5888843 | I8: =AVERAGE(F8:H8) -> 0.58836463 | J8: =AVERAGE(G8:I8) -> 0.58801589 | K8: =AVERAGE(H8:J8) -> 0.58842161 | L8: =AVERAGE(I8:K8) -> 0.58826737
A9: ='Income Statement'!A15 -> Employment Benefit Expenses | B9: ='Income Statement'!B15/'Income Statement'!B$7 -> 0.039895061 | C9: ='Income Statement'!C15/'Income Statement'!C$7 -> 0.041986378 | D9: ='Income Statement'!D15/'Income Statement'!D$7 -> 0.040118758 | E9: =AVERAGE(B9:D9) -> 0.040666732 | F9: =AVERAGE(C9:E9) -> 0.040923956 | G9: =AVERAGE(D9:F9) -> 0.040569815 | H9: =AVERAGE(E9:G9) -> 0.040720168 | I9: =AVERAGE(F9:H9) -> 0.04073798 | J9: =AVERAGE(G9:I9) -> 0.040675988 | K9: =AVERAGE(H9:J9) -> 0.040711378 | L9: =AVERAGE(I9:K9) -> 0.040708449
A10: ='Income Statement'!A16 -> Carriage, freight and distribution | B10: ='Income Statement'!B16/'Income Statement'!B$7 -> 0.050027139 | C10: ='Income Statement'!C16/'Income Statement'!C$7 -> 0.051728597 | D10: ='Income Statement'!D16/'Income Statement'!D$7 -> 0.049862972 | E10: =AVERAGE(B10:D10) -> 0.05053957 | F10: =AVERAGE(C10:E10) -> 0.05071038 | G10: =AVERAGE(D10:F10) -> 0.050370974 | H10: =AVERAGE(E10:G10) -> 0.050540308 | I10: =AVERAGE(F10:H10) -> 0.050540554 | J10: =AVERAGE(G10:I10) -> 0.050483945 | K10: =AVERAGE(H10:J10) -> 0.050521602 | L10: =AVERAGE(I10:K10) -> 0.050515367
A11: ='Income Statement'!A17 -> Advertising and sales promotion | B11: ='Income Statement'!B17/'Income Statement'!B$7 -> 0.04532296 | C11: ='Income Statement'!C17/'Income Statement'!C$7 -> 0.040951806 | D11: ='Income Statement'!D17/'Income Statement'!D$7 -> 0.034409257 | E11: =AVERAGE(B11:D11) -> 0.040228008 | F11: =AVERAGE(C11:E11) -> 0.03852969 | G11: =AVERAGE(D11:F11) -> 0.037722318 | H11: =AVERAGE(E11:G11) -> 0.038826672 | I11: =AVERAGE(F11:H11) -> 0.03835956 | J11: =AVERAGE(G11:I11) -> 0.03830285 | K11: =AVERAGE(H11:J11) -> 0.038496361 | L11: =AVERAGE(I11:K11) -> 0.038386257
A12: ='Income Statement'!A18 -> Conversion charges | B12: ='Income Statement'!B18/'Income Statement'!B$7 -> 0.04640854 | C12: ='Income Statement'!C18/'Income Statement'!C$7 -> 0.043796879 | D12: ='Income Statement'!D18/'Income Statement'!D$7 -> 0.043316078 | E12: =AVERAGE(B12:D12) -> 0.044507166 | F12: =AVERAGE(C12:E12) -> 0.043873374 | G12: =AVERAGE(D12:F12) -> 0.043898873 | H12: =AVERAGE(E12:G12) -> 0.044093137 | I12: =AVERAGE(F12:H12) -> 0.043955128 | J12: =AVERAGE(G12:I12) -> 0.043982379 | K12: =AVERAGE(H12:J12) -> 0.044010215 | L12: =AVERAGE(I12:K12) -> 0.043982574
A13: ='Income Statement'!A19 -> Other Expenses | B13: ='Income Statement'!B19/'Income Statement'!B$7 -> 0.067848743 | C13: ='Income Statement'!C19/'Income Statement'!C$7 -> 0.065436676 | D13: ='Income Statement'!D19/'Income Statement'!D$7 -> 0.06067296 | E13: =AVERAGE(B13:D13) -> 0.064652793 | F13: =AVERAGE(C13:E13) -> 0.063587476 | G13: =AVERAGE(D13:F13) -> 0.062971076 | H13: =AVERAGE(E13:G13) -> 0.063737115 | I13: =AVERAGE(F13:H13) -> 0.063431889 | J13: =AVERAGE(G13:I13) -> 0.063380027 | K13: =AVERAGE(H13:J13) -> 0.063516344 | L13: =AVERAGE(I13:K13) -> 0.063442753
A14: Statutory Tax Rate | B14: =('Income Statement'!B32+'Income Statement'!B33)/'Income Statement'!B31 -> -0.34612407 | C14: =('Income Statement'!C32+'Income Statement'!C33)/'Income Statement'!C31 -> -0.24446072 | D14: =('Income Statement'!D32+'Income Statement'!D33)/'Income Statement'!D31 -> -0.26368391 | E14: =AVERAGE(C14:D14) -> -0.25407231 | F14: =AVERAGE(C14:E14) -> -0.25407231 | G14: =AVERAGE(D14:F14) -> -0.25727618 | H14: =AVERAGE(E14:G14) -> -0.25514027 | I14: =AVERAGE(F14:H14) -> -0.25549625 | J14: =AVERAGE(G14:I14) -> -0.2559709 | K14: =AVERAGE(H14:J14) -> -0.25553581 | L14: =AVERAGE(I14:K14) -> -0.25566765
A16: Balance Sheet
A17: Effective Interest Rate | B17: ='Income Statement'!B26/('Balance Sheet'!B38+'Balance Sheet'!B45) *-1 -> 0.06586002 | C17: ='Income Statement'!C26/('Balance Sheet'!C38+'Balance Sheet'!C45) *-1 -> 0.050790925 | D17: ='Income Statement'!D26/('Balance Sheet'!D38+'Balance Sheet'!D45) *-1 -> 0.053134148 | E17: =AVERAGE(B17:D17) -> 0.056595031 | F17: =AVERAGE(C17:E17) -> 0.053506701 | G17: =AVERAGE(D17:F17) -> 0.05441196 | H17: =AVERAGE(E17:G17) -> 0.054837898 | I17: =AVERAGE(F17:H17) -> 0.054252186 | J17: =AVERAGE(G17:I17) -> 0.054500681 | K17: =AVERAGE(H17:J17) -> 0.054530255 | L17: =AVERAGE(I17:K17) -> 0.054427708
A18: Accounts Receivable Turnover | B18: ='Income Statement'!B8/'Balance Sheet'!B11 -> 28.038758 | C18: ='Income Statement'!C8/'Balance Sheet'!C11 -> 36.206143 | D18: ='Income Statement'!D8/'Balance Sheet'!D11 -> 51.059199 | E18: =AVERAGE(B18:D18) -> 38.4347 | F18: =AVERAGE(C18:E18) -> 41.900014 | G18: =AVERAGE(D18:F18) -> 43.797971 | H18: =AVERAGE(E18:G18) -> 41.377561 | I18: =AVERAGE(F18:H18) -> 42.358515 | J18: =AVERAGE(G18:I18) -> 42.511349 | K18: =AVERAGE(H18:J18) -> 42.082475 | L18: =AVERAGE(I18:K18) -> 42.317447
A19: Inventory Turnover | B19: ='Income Statement'!B13/'Balance Sheet'!B12 * -1 -> 8.3966828 | C19: ='Income Statement'!C13/'Balance Sheet'!C12 * -1 -> 9.3493171 | D19: ='Income Statement'!D13/'Balance Sheet'!D12 * -1 -> 6.9867795 | E19: =AVERAGE(B19:D19) -> 8.2442598 | F19: =AVERAGE(C19:E19) -> 8.1934522 | G19: =AVERAGE(D19:F19) -> 7.8081638 | H19: =AVERAGE(E19:G19) -> 8.0819586 | I19: =AVERAGE(F19:H19) -> 8.0278582 | J19: =AVERAGE(G19:I19) -> 7.9726602 | K19: =AVERAGE(H19:J19) -> 8.0274923 | L19: =AVERAGE(I19:K19) -> 8.0093369
A20: Accounts Payable Turnover | B20: ='Income Statement'!B13/'Balance Sheet'!B37 * -1 -> 5.7526896 | C20: ='Income Statement'!C13/'Balance Sheet'!C37 * -1 -> 6.2058534 | D20: ='Income Statement'!D13/'Balance Sheet'!D37 * -1 -> 5.8003423 | E20: =AVERAGE(B20:D20) -> 5.9196284 | F20: =AVERAGE(C20:E20) -> 5.9752747 | G20: =AVERAGE(D20:F20) -> 5.8984151 | H20: =AVERAGE(E20:G20) -> 5.9311061 | I20: =AVERAGE(F20:H20) -> 5.934932 | J20: =AVERAGE(G20:I20) -> 5.9214844 | K20: =AVERAGE(H20:J20) -> 5.9291741 | L20: =AVERAGE(I20:K20) -> 5.9285302
A21: Depreciation as % of Gross Block | B21: =B44/B39 -> 0.08770924 | C21: =C44/C39 -> 0.08187946 | D21: =D44/D39 -> 0.077828987 | E21: =AVERAGE(B21:D21) -> 0.082472562 | F21: =AVERAGE(C21:E21) -> 0.080727003 | G21: =AVERAGE(D21:F21) -> 0.080342851 | H21: =AVERAGE(E21:G21) -> 0.081180805 | I21: =AVERAGE(F21:H21) -> 0.08075022 | J21: =AVERAGE(G21:I21) -> 0.080757959 | K21: =AVERAGE(H21:J21) -> 0.080896328 | L21: =AVERAGE(I21:K21) -> 0.080801502
A22: Ammortisation as a % of Gross Block | B22: =B59/B55 -> 0.045989758 | C22: =C59/C55 -> 0.017880027 | D22: =D59/D55 -> 0.016474465 | E22: =AVERAGE(B22:D22) -> 0.026781417 | F22: =AVERAGE(C22:E22) -> 0.020378636 | G22: =AVERAGE(D22:F22) -> 0.021211506 | H22: =AVERAGE(E22:G22) -> 0.022790519 | I22: =AVERAGE(F22:H22) -> 0.02146022 | J22: =AVERAGE(G22:I22) -> 0.021820749 | K22: =AVERAGE(H22:J22) -> 0.022023829 | L22: =AVERAGE(I22:K22) -> 0.021768266
A23: Revenue / Gross Block (Tangible) | B23: ='Income Statement'!B8/Assumptions!B32 -> 7.2775393 | C23: ='Income Statement'!C8/Assumptions!C32 -> 5.7367684 | D23: ='Income Statement'!D8/Assumptions!D32 -> 5.4018711 | E23: =AVERAGE(B23:D23) -> 6.1387263 | F23: =AVERAGE(C23:E23) -> 5.7591219 | G23: =AVERAGE(D23:F23) -> 5.7665731 | H23: =AVERAGE(E23:G23) -> 5.8881404 | I23: =AVERAGE(F23:H23) -> 5.8046118 | J23: =AVERAGE(G23:I23) -> 5.8197751 | K23: =AVERAGE(H23:J23) -> 5.8375091 | L23: =AVERAGE(I23:K23) -> 5.820632
A24: Revenue / Gross Block (Intangible) | B24: ='Income Statement'!B8/B50 -> 74.257692 | C24: ='Income Statement'!C8/C50 -> 73.537057 | D24: ='Income Statement'!D8/D50 -> 77.266043 | E24: =AVERAGE(B24:D24) -> 75.020264 | F24: =AVERAGE(C24:E24) -> 75.274455 | G24: =AVERAGE(D24:F24) -> 75.853587 | H24: =AVERAGE(E24:G24) -> 75.382769 | I24: =AVERAGE(F24:H24) -> 75.503604 | J24: =AVERAGE(G24:I24) -> 75.579987 | K24: =AVERAGE(H24:J24) -> 75.488786 | L24: =AVERAGE(I24:K24) -> 75.524125
A26: Debt/Equity | B26: ='Balance Sheet'!B45/'Balance Sheet'!B59 -> 0.014447273 | C26: ='Balance Sheet'!C45/'Balance Sheet'!C59 -> 0.17259512 | D26: ='Balance Sheet'!D45/'Balance Sheet'!D59 -> 0.2086356 | E26: =AVERAGE(B26:D26) -> 0.13189267 | F26: =AVERAGE(C26:E26) -> 0.17104113 | G26: =AVERAGE(D26:F26) -> 0.17052313 | H26: =AVERAGE(E26:G26) -> 0.15781898 | I26: =AVERAGE(F26:H26) -> 0.16646108 | J26: =AVERAGE(G26:I26) -> 0.1649344 | K26: =AVERAGE(H26:J26) -> 0.16307148 | L26: =AVERAGE(I26:K26) -> 0.16482232
A27: Other Liabilities turnover | B27: ='Income Statement'!B13/'Balance Sheet'!B39 *-1 -> 18.003951 | C27: ='Income Statement'!C13/'Balance Sheet'!C39 *-1 -> 14.994848 | D27: ='Income Statement'!D13/'Balance Sheet'!D39 *-1 -> 15.35797 | E27: =AVERAGE(B27:D27) -> 16.118923 | F27: =AVERAGE(C27:E27) -> 15.490581 | G27: =AVERAGE(D27:F27) -> 15.655825 | H27: =AVERAGE(E27:G27) -> 15.755109 | I27: =AVERAGE(F27:H27) -> 15.633838 | J27: =AVERAGE(G27:I27) -> 15.681591 | K27: =AVERAGE(H27:J27) -> 15.690179 | L27: =AVERAGE(I27:K27) -> 15.668536
A28: Dividend payout ratio | B28: ='Income Statement'!B51/'Income Statement'!B41 -> -0.30526842 | C28: ='Income Statement'!C51/'Income Statement'!C41 -> -0.3093765 | D28: ='Income Statement'!D51/'Income Statement'!D41 -> -1.5264091 | E28: =0.31*-1 -> -0.31 | F28: =0.31*-1 -> -0.31 | G28: =0.31*-1 -> -0.31 | H28: =0.31*-1 -> -0.31 | I28: =0.31*-1 -> -0.31 | J28: =0.31*-1 -> -0.31 | K28: =0.31*-1 -> -0.31 | L28: =0.31*-1 -> -0.31
A30: ASSET SCHEDULE
A31: Tangible Assets
A32: Gross Assets (Opening) | B32: 1518.92 | C32: 2021.87 | D32: 2431.75 | E32: =D38 -> 2573.84 | F32: =E38 -> 2766.4272 | G32: =F38 -> 2990.1838 | H32: =G38 -> 3233.7634 | I32: =H38 -> 3493.7835 | J32: =I38 -> 3781.2839 | K32: =J38 -> 4093.8428 | L32: =K38 -> 4433.4971
A33: Acquisitions | B33: 493.18 | C33: 320.93 | D33: 111.35 | E33: =('Income Statement'!E8-'Income Statement'!D8)/E23 -> 192.58718 | F33: =('Income Statement'!F8-'Income Statement'!E8)/F23 -> 223.75661 | G33: =('Income Statement'!G8-'Income Statement'!F8)/G23 -> 243.57956 | H33: =('Income Statement'!H8-'Income Statement'!G8)/H23 -> 260.02014 | I33: =('Income Statement'!I8-'Income Statement'!H8)/I23 -> 287.5004 | J33: =('Income Statement'!J8-'Income Statement'!I8)/J23 -> 312.55895 | K33: =('Income Statement'!K8-'Income Statement'!J8)/K23 -> 339.65426 | L33: =('Income Statement'!L8-'Income Statement'!K8)/L23 -> 371.29662
A34: Transitions | C34: 37.87 | E34: 0 | F34: 0 | G34: 0 | H34: 0 | I34: 0 | J34: 0 | K34: 0 | L34: 0
A35: Exchange Difference | B35: 23.42 | C35: 56.47 | D35: 47.28 | E35: 0 | F35: 0 | G35: 0 | H35: 0 | I35: 0 | J35: 0 | K35: 0 | L35: 0
A36: Adjustments | C36: 0 | D36: 2.29 | E36: 0 | F36: 0 | G36: 0 | H36: 0 | I36: 0 | J36: 0 | K36: 0 | L36: 0
A37: Disposal | B37: 13.65 | C37: 5.39 | D37: 18.83 | E37: 0 | F37: 0 | G37: 0 | H37: 0 | I37: 0 | J37: 0 | K37: 0 | L37: 0
A38: Gross Assets (Ending) | B38: =SUM(B32:B36)-B37 -> 2021.87 | C38: =SUM(C32:C36)-C37 -> 2431.75 | D38: =SUM(D32:D36)-D37 -> 2573.84 | E38: =SUM(E32:E36)-E37 -> 2766.4272 | F38: =SUM(F32:F36)-F37 -> 2990.1838 | G38: =SUM(G32:G36)-G37 -> 3233.7634 | H38: =SUM(H32:H36)-H37 -> 3493.7835 | I38: =SUM(I32:I36)-I37 -> 3781.2839 | ... L38: =SUM(L32:L36)-L37 -> 4804.7937
A39: Average Gross Block | B39: =AVERAGE(B32,B38) -> 1770.395 | C39: =AVERAGE(C32,C38) -> 2226.81 | D39: =AVERAGE(D32,D38) -> 2502.795 | E39: =AVERAGE(E32,E38) -> 2670.1336 | F39: =AVERAGE(F32,F38) -> 2878.3055 | G39: =AVERAGE(G32,G38) -> 3111.9736 | H39: =AVERAGE(H32,H38) -> 3363.7734 | I39: =AVERAGE(I32,I38) -> 3637.5337 | ... L39: =AVERAGE(L32,L38) -> 4619.1454
A41: Depreciation
A42: Accumulated Depreciation (Opening) | B42: 324.48 | C42: 486.29 | D42: 715.38 | E42: =D46 -> 939.54 | F42: =E46 -> 1159.7528 | G42: =F46 -> 1392.1097 | H42: =G46 -> 1642.1346 | I42: =H46 -> 1915.2084 | J42: =I46 -> 2208.94 | K42: =J46 -> 2526.9296 | L42: =K46 -> 2871.8449
A43: Accumulated Depreciation On Acquisitions During The Year/exchange difference | B43: 19.33 | C43: 51.53 | D43: 46.36 | E43: 0 | F43: 0 | G43: 0 | H43: 0 | I43: 0 | J43: 0 | K43: 0 | L43: 0
A44: Depreciation For The Year | B44: 155.28 | C44: 182.33 | D44: 194.79 | E44: =E21*E39 -> 220.21276 | F44: =F21*F39 -> 232.35698 | G44: =G21*G39 -> 250.02483 | H44: =H21*H39 -> 273.07384 | I44: =I21*I39 -> 293.73165 | J44: =J21*J39 -> 317.98958 | K44: =K21*K39 -> 344.91524 | L44: =L21*L39 -> 373.23389
A45: Disposal | B45: 12.8 | C45: 4.77 | D45: 16.99 | E45: 0 | F45: 0 | G45: 0 | H45: 0 | I45: 0 | J45: 0 | K45: 0 | L45: 0
A46: Accumulated Depreciation (Ending) | B46: =SUM(B42:B44)-B45 -> 486.29 | C46: =SUM(C42:C44)-C45 -> 715.38 | D46: =SUM(D42:D44)-D45 -> 939.54 | E46: =SUM(E42:E44)-E45 -> 1159.7528 | F46: =SUM(F42:F44)-F45 -> 1392.1097 | G46: =SUM(G42:G44)-G45 -> 1642.1346 | H46: =SUM(H42:H44)-H45 -> 1915.2084 | I46: =SUM(I42:I44)-I45 -> 2208.94 | ... L46: =SUM(L42:L44)-L45 -> 3245.0788
...

Sheet Income Statement
A1: Britannia Limited
A2: INCOME STATEMENTS
A6: Particulars | B6: =Assumptions!B5 -> FY2019 A | C6: =Assumptions!C5 -> FY2020 A | D6: =Assumptions!D5 -> FY2021 A | E6: =Assumptions!E5 -> FY2022 E | F6: =Assumptions!F5 -> FY2023 E | G6: =Assumptions!G5 -> FY2024 E | H6: =Assumptions!H5 -> FY2025 E | I6: =Assumptions!I5 -> FY2026 E | ... L6: =Assumptions!L5 -> FY2029 E
A7: Revenue from Operation | B7: 11054 | C7: 11599 | D7: 13136 | E7: =D7+D7*Assumptions!E7 -> 14318.24 | F7: =E7+E7*Assumptions!F7 -> 15606.882 | G7: =F7+F7*Assumptions!G7 -> 17011.501 | H7: =G7+G7*Assumptions!H7 -> 18542.536 | I7: =H7+H7*Assumptions!I7 -> 20211.364 | J7: =I7+I7*Assumptions!J7 -> 22030.387 | K7: =J7+J7*Assumptions!K7 -> 24013.122 | L7: =K7+K7*Assumptions!L7 -> 26174.303
A8: Total Income | B8: =SUM(B7:B7) -> 11054 | C8: =SUM(C7:C7) -> 11599 | D8: =SUM(D7:D7) -> 13136 | E8: =SUM(E7:E7) -> 14318.24 | F8: =SUM(F7:F7) -> 15606.882 | G8: =SUM(G7:G7) -> 17011.501 | H8: =SUM(H7:H7) -> 18542.536 | I8: =SUM(I7:I7) -> 20211.364 | ... L8: =SUM(L7:L7) -> 26174.303
A9: Cost of materials consumed | B9: -5513 | C9: -5901.16 | D9: -6502 | E9: =E8*Assumptions!E8*-1 -> -8454.1093 | F9: =F8*Assumptions!F8*-1 -> -9198.8653 | G9: =G8*Assumptions!G8*-1 -> -9982.3272 | H9: =H8*Assumptions!H8*-1 -> -10919.408 | I9: =I8*Assumptions!I8*-1 -> -11891.652 | J9: =J8*Assumptions!J8*-1 -> -12954.218 | K9: =K8*Assumptions!K8*-1 -> -14129.84 | L9: =L8*Assumptions!L8*-1 -> -15397.488
A10: Purchase | B10: -1103 | C10: -973.74 | D10: -1161 | E10: 0 | F10: 0 | G10: 0 | H10: 0 | I10: 0 | J10: 0 | K10: 0 | L10: 0
A11: Excise Duty | B11: 0 | C11: 0 | D11: 0
A12: Changes in stock | B12: 55 | C12: -52.57 | D12: 37 | E12: 0 | F12: 0 | G12: 0 | H12: 0 | I12: 0 | J12: 0 | K12: 0 | L12: 0
A13: Cost of Goods Sold | B13: =SUM(B9:B12) -> -6561 | C13: =SUM(C9:C12) -> -6927.47 | D13: =SUM(D9:D12) -> -7626 | E13: =SUM(E9:E12) -> -8454.1093 | F13: =SUM(F9:F12) -> -9198.8653 | G13: =SUM(G9:G12) -> -9982.3272 | H13: =SUM(H9:H12) -> -10919.408 | I13: =SUM(I9:I12) -> -11891.652 | ... L13: =SUM(L9:L12) -> -15397.488
A14: Gross Profit | B14: =B8+B13 -> 4493 | C14: =C8+C13 -> 4671.53 | D14: =D8+D13 -> 5510 | E14: =E8+E13 -> 5864.1307 | F14: =F8+F13 -> 6408.0163 | G14: =G8+G13 -> 7029.1737 | H14: =H8+H13 -> 7623.1276 | I14: =I8+I13 -> 8319.7125 | ... L14: =L8+L13 -> 10776.814
A15: Employment Benefit Expenses | B15: 441 | C15: 487 | D15: 527 | E15: =E$7*Assumptions!E9 -> 582.27603 | F15: =F$7*Assumptions!F9 -> 638.69534 | G15: =G$7*Assumptions!G9 -> 690.15345 | H15: =H$7*Assumptions!H9 -> 755.05518 | I15: =I$7*Assumptions!I9 -> 823.37015 | J15: =J$7*Assumptions!J9 -> 896.10775 | K15: =K$7*Assumptions!K9 -> 977.60729 | L15: =L$7*Assumptions!L9 -> 1065.5153
A16: Carriage, freight and distribution | B16: 553 | C16: 600 | D16: 655 | E16: =E$7*Assumptions!E10 -> 723.63769 | F16: =F$7*Assumptions!F10 -> 791.43089 | G16: =G$7*Assumptions!G10 -> 856.88587 | H16: =H$7*Assumptions!H10 -> 937.14548 | I16: =I$7*Assumptions!I10 -> 1021.4935 | J16: =J$7*Assumptions!J10 -> 1112.1808 | K16: =K$7*Assumptions!K10 -> 1213.1814 | L16: =L$7*Assumptions!L10 -> 1322.2045
A17: Advertising and sales promotion | B17: 501 | C17: 475 | D17: 452 | E17: =E$7*Assumptions!E11 -> 575.99427 | F17: =F$7*Assumptions!F11 -> 601.32831 | G17: =G$7*Assumptions!G11 -> 641.71325 | H17: =H$7*Assumptions!H11 -> 719.94497 | I17: =I$7*Assumptions!I11 -> 775.29905 | J17: =J$7*Assumptions!J11 -> 843.82662 | K17: =K$7*Assumptions!K11 -> 924.41781 | L17: =L$7*Assumptions!L11 -> 1004.7335
A18: Conversion charges | B18: 513 | C18: 508 | D18: 569 | E18: =E$7*Assumptions!E12 -> 637.26428 | F18: =F$7*Assumptions!F12 -> 684.72656 | G18: =G$7*Assumptions!G12 -> 746.78571 | H18: =H$7*Assumptions!H12 -> 817.59859 | I18: =I$7*Assumptions!I12 -> 888.39311 | J18: =J$7*Assumptions!J12 -> 968.94884 | K18: =K$7*Assumptions!K12 -> 1056.8227 | L18: =L$7*Assumptions!L12 -> 1151.2132
A19: Other Expenses | B19: =2317 -SUM(B16:B18) -> 750 | C19: =2342-SUM(C16:C18) -> 759 | D19: =2473-SUM(D16:D18) -> 797 | E19: =E$7*Assumptions!E13 -> 925.7142 | F19: =F$7*Assumptions!F13 -> 992.40221 | G19: =G$7*Assumptions!G13 -> 1071.2325 | H19: =H$7*Assumptions!H13 -> 1181.8478 | I19: =I$7*Assumptions!I13 -> 1282.045 | J19: =J$7*Assumptions!J13 -> 1396.2865 | K19: =K$7*Assumptions!K13 -> 1525.2257 | L19: =L$7*Assumptions!L13 -> 1660.5698
A20: Other Expense 2 | B20: 0 | C20: 0 | D20: 0 | E20: 0 | F20: 0 | G20: 0 | H20: 0 | I20: 0 | J20: 0 | K20: 0 | L20: 0
A21: Other Expense 3 | B21: 0 | C21: 0 | D21: 0 | E21: 0 | F21: 0 | G21: 0 | H21: 0 | I21: 0 | J21: 0 | K21: 0 | L21: 0
A22: Total Expenditure | B22: =SUM(B15:B21) -> 2758 | C22: =SUM(C15:C21) -> 2829 | D22: =SUM(D15:D21) -> 3000 | E22: =SUM(E15:E21) -> 3444.8865 | F22: =SUM(F15:F21) -> 3708.5833 | G22: =SUM(G15:G21) -> 4006.7708 | H22: =SUM(H15:H21) -> 4411.592 | I22: =SUM(I15:I21) -> 4790.6009 | ... L22: =SUM(L15:L21) -> 6204.2363
A23: EBITDA | B23: =B14-B22 -> 1735 | C23: =C14-C22 -> 1842.53 | D23: =D14-D22 -> 2510 | E23: =E14-E22 -> 2419.2442 | F23: =F14-F22 -> 2699.433 | G23: =G14-G22 -> 3022.4029 | H23: =H14-H22 -> 3211.5357 | I23: =I14-I22 -> 3529.1116 | ... L23: =L14-L22 -> 4572.5781
A24: Depreciation & Ammortization | B24: -161.88 | C24: -184.81 | D24: -197.85 | E24: =(Assumptions!E44+Assumptions!E59)*-1 -> -224.97421 | F24: =(Assumptions!F44+Assumptions!F59)*-1 -> -236.31509 | G24: =(Assumptions!G44+Assumptions!G59)*-1 -> -254.52266 | H24: =(Assumptions!H44+Assumptions!H59)*-1 -> -278.34895 | I24: =(Assumptions!I44+Assumptions!I59)*-1 -> -299.15394 | J24: =(Assumptions!J44+Assumptions!J59)*-1 -> -324.0067 | K24: =(Assumptions!K44+Assumptions!K59)*-1 -> -351.54263 | L24: =(Assumptions!L44+Assumptions!L59)*-1 -> -380.3817
A25: EBIT | B25: =B23+B24 -> 1573.12 | C25: =C23+C24 -> 1657.72 | D25: =D23+D24 -> 2312.15 | E25: =E23+E24 -> 2194.27 | F25: =F23+F24 -> 2463.118 | G25: =G23+G24 -> 2767.8803 | H25: =H23+H24 -> 2933.1867 | I25: =I23+I24 -> 3229.9577 | ... L25: =L23+L24 -> 4192.1964
A26: Interest | B26: -9.09 | C26: -76.9 | D26: -110.9 | E26: =Assumptions!E17*('Balance Sheet'!E45+'Balance Sheet'!E38) *-1 -> -118.12345 | F26: =Assumptions!F17*('Balance Sheet'!F45+'Balance Sheet'!F38) *-1 -> -111.67758 | G26: =Assumptions!G17*('Balance Sheet'!G45+'Balance Sheet'!G38) *-1 -> -113.56701 | H26: =Assumptions!H17*('Balance Sheet'!H45+'Balance Sheet'!H38) *-1 -> -114.45601 | I26: =Assumptions!I17*('Balance Sheet'!I45+'Balance Sheet'!I38) *-1 -> -113.23354 | J26: =Assumptions!J17*('Balance Sheet'!J45+'Balance Sheet'!J38) *-1 -> -113.75219 | K26: =Assumptions!K17*('Balance Sheet'!K45+'Balance Sheet'!K38) *-1 -> -113.81391 | L26: =Assumptions!L17*('Balance Sheet'!L45+'Balance Sheet'!L38) *-1 -> -113.59988
A27: Other Income | B27: 206.45 | C27: 279.4 | D27: 313 | E27: =D27 -> 313 | F27: =E27 -> 313 | G27: =F27 -> 313 | H27: =G27 -> 313 | I27: =H27 -> 313 | J27: =I27 -> 313 | K27: =J27 -> 313 | L27: =K27 -> 313
A28: Profit before Prior Period Items and Tax | B28: =B25+B26+B27 -> 1770.48 | C28: =C25+C26+C27 -> 1860.22 | D28: =D25+D26+D27 -> 2514.25 | E28: =E25+E26+E27 -> 2389.1465 | F28: =F25+F26+F27 -> 2664.4404 | G28: =G25+G26+G27 -> 2967.3133 | H28: =H25+H26+H27 -> 3131.7307 | I28: =I25+I26+I27 -> 3429.7242 | ... L28: =L25+L26+L27 -> 4391.5966
A29: Exceptional Items | B29: 0 | C29: -17.01 | D29: -0.61 | E29: 0 | F29: 0 | G29: 0 | H29: 0 | I29: 0 | J29: 0 | K29: 0 | L29: 0
A30: Share of loss/profits of associates | B30: -0.97 | C30: 0.44 | D30: 0.81 | E30: 1 | F30: 1 | G30: 1 | H30: 1 | I30: 1 | J30: 1 | K30: 1 | L30: 1
A31: Profit/Loss before Taxation | B31: =B28+B29+B30 -> 1769.51 | C31: =C28+C29+C30 -> 1843.65 | D31: =D28+D29+D30 -> 2514.45 | E31: =E28+E29+E30 -> 2390.1465 | F31: =F28+F29+F30 -> 2665.4404 | G31: =G28+G29+G30 -> 2968.3133 | H31: =H28+H29+H30 -> 3132.7307 | I31: =I28+I29+I30 -> 3430.7242 | ... L31: =L28+L29+L30 -> 4392.5966
A32: Current Tax | B32: -599.78 | C32: -447.69 | D32: -657.12 | E32: =E31*Assumptions!E14 -> -607.27005 | F32: =F31*Assumptions!F14 -> -677.2146 | G32: =G31*Assumptions!G14 -> -763.67629 | H32: =H31*Assumptions!H14 -> -799.28575 | I32: =I31*Assumptions!I14 -> -876.53716 | J32: =J31*Assumptions!J14 -> -956.06666 | K32: =K31*Assumptions!K14 -> -1031.0028 | L32: =L31*Assumptions!L14 -> -1123.0448
A33: Provision for Deferred tax | B33: -12.69 | C33: -3.01 | D33: -5.9 | E33: 0 | F33: 0 | G33: 0 | H33: 0 | I33: 0 | J33: 0 | K33: 0 | L33: 0
A34: Other Tax | B34: 0 | C34: 0 | D34: 0 | E34: 0 | F34: 0 | G34: 0 | H34: 0 | I34: 0 | J34: 0 | K34: 0 | L34: 0
A35: Profit/Loss after Tax | B35: =SUM(B31:B34) -> 1157.04 | C35: =SUM(C31:C34) -> 1392.95 | D35: =SUM(D31:D34) -> 1851.43 | E35: =E31+E32 -> 1782.8765 | F35: =F31+F32 -> 1988.2258 | G35: =G31+G32 -> 2204.637 | H35: =H31+H32 -> 2333.445 | I35: =I31+I32 -> 2554.187 | J35: =J31+J32 -> 2778.9933 | K35: =K31+K32 -> 3003.6679 | L35: =L31+L32 -> 3269.5517
A36: Other Comprehensive Income
A37: Reassesment of defined benefit | B37: -4.09 | C37: -6.5 | D37: 3.5 | E37: 0 | F37: 0 | G37: 0 | H37: 0 | I37: 0 | J37: 0 | K37: 0 | L37: 0
A38: Income tax related income | B38: 1.43 | C38: 1.57 | D38: -0.92 | E38: 0 | F38: 0 | G38: 0 | H38: 0 | I38: 0 | J38: 0 | K38: 0 | L38: 0
A39: Foreign Currency translation reserve | B39: 6.5 | C39: 10.05 | D39: -4.08 | E39: 0 | F39: 0 | G39: 0 | H39: 0 | I39: 0 | J39: 0 | K39: 0 | L39: 0
A40: Item #4 | B40: 0 | C40: 0 | D40: 0 | E40: 0 | F40: 0 | G40: 0 | H40: 0 | I40: 0 | J40: 0 | K40: 0 | L40: 0
A41: Total Comprehensive Income to common shareholders | B41: =SUM(B37:B40)+B35 -> 1160.88 | C41: =SUM(C37:C40)+C35 -> 1398.07 | D41: =SUM(D37:D40)+D35 -> 1849.93 | E41: =SUM(E37:E40)+E35 -> 1782.8765 | F41: =SUM(F37:F40)+F35 -> 1988.2258 | G41: =SUM(G37:G40)+G35 -> 2204.637 | H41: =SUM(H37:H40)+H35 -> 2333.445 | I41: =SUM(I37:I40)+I35 -> 2554.187 | ... L41: =SUM(L37:L40)+L35 -> 3269.5517
A42: Minority Interests | B42: 3.66 | C42: 9.03 | D42: 13.31 | E42: =D42 -> 13.31 | F42: =E42 -> 13.31 | G42: =F42 -> 13.31 | H42: =G42 -> 13.31 | I42: =H42 -> 13.31 | J42: =I42 -> 13.31 | K42: =J42 -> 13.31 | L42: =K42 -> 13.31
A44: Number of Shares Issued:
...

Sheet Balance Sheet
A1: =Dashboard!A1 -> [Britannia LTD.]
A2: Balance Sheet
A3: (in INR Crores)
A5: =Assumptions!A5 -> Particular | B5: =Assumptions!B5 -> FY2019 A | C5: =Assumptions!C5 -> FY2020 A | D5: =Assumptions!D5 -> FY2021 A | E5: =Assumptions!E5 -> FY2022 E | F5: =Assumptions!F5 -> FY2023 E | G5: =Assumptions!G5 -> FY2024 E | H5: =Assumptions!H5 -> FY2025 E | ... L5: =Assumptions!L5 -> FY2029 E
A6: Assets
A8: Cash And Cash Equivalents | B8: 60.32 | C8: 81.23 | D8: 142.74 | E8: =CFS!E71 -> 1480.3768 | F8: =CFS!F71 -> 2931.1837 | G8: =CFS!G71 -> 4469.8027 | H8: =CFS!H71 -> 6149.6658 | I8: =CFS!I71 -> 7972.567 | J8: =CFS!J71 -> 9942.2825 | K8: =CFS!K71 -> 12082.604 | L8: =CFS!L71 -> 14405.129
A9: Bank Balance | B9: 49.5 | C9: 41.62 | D9: 68.6 | E9: 68.6 | F9: =E9 -> 68.6 | G9: =F9 -> 68.6 | H9: =G9 -> 68.6 | I9: =H9 -> 68.6 | J9: =I9 -> 68.6 | K9: =J9 -> 68.6 | L9: =K9 -> 68.6
A10: Current Investment | B10: 749.88 | C10: 1008.77 | D10: 1393.25 | E10: =D10 -> 1393.25 | F10: =E10 -> 1393.25 | G10: =F10 -> 1393.25 | H10: =G10 -> 1393.25 | I10: =H10 -> 1393.25 | J10: =I10 -> 1393.25 | K10: =J10 -> 1393.25 | L10: =K10 -> 1393.25
A11: Accounts Receivables | B11: 394.24 | C11: 320.36 | D11: 257.27 | E11: ='Income Statement'!E8/Assumptions!E18 -> 372.5342 | F11: ='Income Statement'!F8/Assumptions!F18 -> 372.47915 | G11: ='Income Statement'!G8/Assumptions!G18 -> 388.40843 | H11: ='Income Statement'!H8/Assumptions!H18 -> 448.13023 | I11: ='Income Statement'!I8/Assumptions!I18 -> 477.14997 | J11: ='Income Statement'!J8/Assumptions!J18 -> 518.22366 | K11: ='Income Statement'!K8/Assumptions!K18 -> 570.62047 | L11: ='Income Statement'!L8/Assumptions!L18 -> 618.52274
A12: Inventories | B12: 781.38 | C12: 740.96 | D12: 1091.49 | E12: ='Income Statement'!E13/Assumptions!E19 * -1 -> 1025.454 | F12: ='Income Statement'!F13/Assumptions!F19 * -1 -> 1122.7093 | G12: ='Income Statement'!G13/Assumptions!G19 * -1 -> 1278.4475 | H12: ='Income Statement'!H13/Assumptions!H19 * -1 -> 1351.0844 | I12: ='Income Statement'!I13/Assumptions!I19 * -1 -> 1481.2982 | J12: ='Income Statement'!J13/Assumptions!J19 * -1 -> 1624.83 | K12: ='Income Statement'!K13/Assumptions!K19 * -1 -> 1760.181 | L12: ='Income Statement'!L13/Assumptions!L19 * -1 -> 1922.4423
A13: Short-Term Loans And Advances | B13: 1203.92 | C13: 1110.11 | D13: 946.56 | E13: =D13 -> 946.56 | F13: =E13 -> 946.56 | G13: =F13 -> 946.56 | H13: =G13 -> 946.56 | I13: =H13 -> 946.56 | J13: =I13 -> 946.56 | K13: =J13 -> 946.56 | L13: =K13 -> 946.56
A14: Other Current Assets | B14: 160.81 | C14: 142.17 | D14: 397.76 | E14: =D14 -> 397.76 | F14: =E14 -> 397.76 | G14: =F14 -> 397.76 | H14: =G14 -> 397.76 | I14: =H14 -> 397.76 | J14: =I14 -> 397.76 | K14: =J14 -> 397.76 | L14: =K14 -> 397.76
A15: Other Financial Assets | B15: 126.29 | C15: 229.75 | D15: 122.01 | E15: =D15 -> 122.01 | F15: =E15 -> 122.01 | G15: =F15 -> 122.01 | H15: =G15 -> 122.01 | I15: =H15 -> 122.01 | J15: =I15 -> 122.01 | K15: =J15 -> 122.01 | L15: =K15 -> 122.01
A16: Other Items 2 | B16: 0 | C16: 0 | D16: 0 | E16: 0 | F16: 0 | G16: 0 | H16: 0 | I16: 0 | J16: 0 | K16: 0 | L16: 0
A17: Other Current Assets 3 | B17: 0 | C17: 0 | D17: 0 | E17: 0 | F17: 0 | G17: 0 | H17: 0 | I17: 0 | J17: 0 | K17: 0 | L17: 0
A18: Total Current Assets | B18: =SUM(B8:B17) -> 3526.34 | C18: =SUM(C8:C17) -> 3674.97 | D18: =SUM(D8:D17) -> 4419.68 | E18: =SUM(E8:E17) -> 5806.545 | F18: =SUM(F8:F17) -> 7354.5522 | G18: =SUM(G8:G17) -> 9064.8385 | H18: =SUM(H8:H17) -> 10877.06 | I18: =SUM(I8:I17) -> 12859.195 | ... L18: =SUM(L8:L17) -> 19874.274
A20: PPE, Net | B20: 1535.58 | C20: 1716.37 | D20: 1634.3 | E20: =Assumptions!E47 -> 1606.6744 | F20: =Assumptions!F47 -> 1598.0741 | G20: =Assumptions!G47 -> 1591.6288 | H20: =Assumptions!H47 -> 1578.5751 | I20: =Assumptions!I47 -> 1572.3439 | J20: =Assumptions!J47 -> 1566.9132 | K20: =Assumptions!K47 -> 1561.6522 | L20: =Assumptions!L47 -> 1559.715
A21: Other Intangible Assets | B21: 7.62 | C21: 8.37 | D21: 8.54 | E21: =Assumptions!E62 -> 155.43749 | F21: =Assumptions!F62 -> 168.59862 | G21: =Assumptions!G62 -> 182.61829 | H21: =Assumptions!H62 -> 197.65332 | I21: =Assumptions!I62 -> 214.33366 | J21: =Assumptions!J62 -> 232.38406 | K21: =Assumptions!K62 -> 252.02197 | L21: =Assumptions!L62 -> 273.48993
A22: Capital Work-In-Progress | B22: 101.24 | C22: 39.55 | D22: 116.52 | E22: =D22 -> 116.52 | F22: =E22 -> 116.52 | G22: =F22 -> 116.52 | H22: =G22 -> 116.52 | I22: =H22 -> 116.52 | J22: =I22 -> 116.52 | K22: =J22 -> 116.52 | L22: =K22 -> 116.52
A23: Investment Property | B23: 14.73 | C23: 14.47 | D23: 14.21 | E23: =D23 -> 14.21 | F23: =E23 -> 14.21 | G23: =F23 -> 14.21 | H23: =G23 -> 14.21 | I23: =H23 -> 14.21 | J23: =I23 -> 14.21 | K23: =J23 -> 14.21 | L23: =K23 -> 14.21
A24: Goodwill on Consolidation | B24: 130.37 | C24: 138.97 | D24: 135.9 | E24: 0 | F24: 0 | G24: 0 | H24: 0 | I24: 0 | J24: 0 | K24: 0 | L24: 0
A25: Long-Term Investments | B25: 725.36 | C25: 1882.98 | D25: 1385.15 | E25: =D25 -> 1385.15 | F25: =E25 -> 1385.15 | G25: =F25 -> 1385.15 | H25: =G25 -> 1385.15 | I25: =H25 -> 1385.15 | J25: =I25 -> 1385.15 | K25: =J25 -> 1385.15 | L25: =K25 -> 1385.15
A26: Deferred Tax Assets (Net) | B26: 13.75 | C26: 19.56 | D26: =9.66+71.84 -> 81.5 | E26: =D26 -> 81.5 | F26: =E26 -> 81.5 | G26: =F26 -> 81.5 | H26: =G26 -> 81.5 | I26: =H26 -> 81.5 | J26: =I26 -> 81.5 | K26: =J26 -> 81.5 | L26: =K26 -> 81.5
A27: Long-Term Loans And Advances | B27: 19.02 | C27: 202.95 | D27: 74.58 | E27: =D27 -> 74.58 | F27: =E27 -> 74.58 | G27: =F27 -> 74.58 | H27: =G27 -> 74.58 | I27: =H27 -> 74.58 | J27: =I27 -> 74.58 | K27: =J27 -> 74.58 | L27: =K27 -> 74.58
A28: Investment In Associates | B28: 1.04 | C28: 1.48 | D28: 2.29 | E28: =D28 -> 2.29 | F28: =E28 -> 2.29 | G28: =F28 -> 2.29 | H28: =G28 -> 2.29 | I28: =H28 -> 2.29 | J28: =I28 -> 2.29 | K28: =J28 -> 2.29 | L28: =K28 -> 2.29
A29: Other Financial Assets | B29: 28.67 | C29: 31.33 | D29: 30.13 | E29: =D29 -> 30.13 | F29: =E29 -> 30.13 | G29: =F29 -> 30.13 | H29: =G29 -> 30.13 | I29: =H29 -> 30.13 | J29: =I29 -> 30.13 | K29: =J29 -> 30.13 | L29: =K29 -> 30.13
A30: Other Non Current Assets | B30: =37.02+101.08 -> 138.1 | C30: =68.77+42.46 -> 111.23 | D30: 105.98 | E30: =D30 -> 105.98 | F30: =E30 -> 105.98 | G30: =F30 -> 105.98 | H30: =G30 -> 105.98 | I30: =H30 -> 105.98 | J30: =I30 -> 105.98 | K30: =J30 -> 105.98 | L30: =K30 -> 105.98
A31: Other items 3 | B31: 0 | C31: 0 | D31: 0
A32: Total Non-Current Assets | B32: =SUM(B20:B31) -> 2715.48 | C32: =SUM(C20:C31) -> 4167.26 | D32: =SUM(D20:D31) -> 3589.1 | E32: =SUM(E20:E31) -> 3572.4719 | F32: =SUM(F20:F31) -> 3577.0327 | G32: =SUM(G20:G31) -> 3584.6071 | H32: =SUM(H20:H31) -> 3586.5884 | I32: =SUM(I20:I31) -> 3597.0375 | ... L32: =SUM(L20:L31) -> 3643.5649
A33: Total Assets | B33: =B18+B32 -> 6241.82 | C33: =C18+C32 -> 7842.23 | D33: =D18+D32 -> 8008.78 | E33: =E18+E32 -> 9379.0169 | F33: =F18+F32 -> 10931.585 | G33: =G18+G32 -> 12649.446 | H33: =H18+H32 -> 14463.649 | I33: =I18+I32 -> 16456.233 | ... L33: =L18+L32 -> 23517.839
A35: LIABILITIES & EQUITY
A37: Accounts Payable | B37: =1.78+1138.73 -> 1140.51 | C37: =8.53+1107.75 -> 1116.28 | D37: =28.44+1286.31 -> 1314.75 | E37: ='Income Statement'!E13/Assumptions!E20 * -1 -> 1428.1487 | F37: ='Income Statement'!F13/Assumptions!F20 * -1 -> 1539.4883 | G37: ='Income Statement'!G13/Assumptions!G20 * -1 -> 1692.3745 | H37: ='Income Statement'!H13/Assumptions!H20 * -1 -> 1841.0408 | I37: ='Income Statement'!I13/Assumptions!I20 * -1 -> 2003.6711 | J37: ='Income Statement'!J13/Assumptions!J20 * -1 -> 2187.6639 | K37: ='Income Statement'!K13/Assumptions!K20 * -1 -> 2383.1042 | L37: ='Income Statement'!L13/Assumptions!L20 * -1 -> 2597.1848
A38: Short-Term Borrowings | B38: 76.1 | C38: 747.99 | D38: 1339.42 | E38: =D38 -> 1339.42 | F38: =E38 -> 1339.42 | G38: =F38 -> 1339.42 | H38: =G38 -> 1339.42 | I38: =H38 -> 1339.42 | J38: =I38 -> 1339.42 | K38: =J38 -> 1339.42 | L38: =K38 -> 1339.42
A39: Other Current Liabilities | B39: =269.2+95.22 -> 364.42 | C39: =311.91+150.08 -> 461.99 | D39: =356.01+140.54 -> 496.55 | E39: ='Income Statement'!E13/Assumptions!E27 *-1 -> 524.4835 | F39: ='Income Statement'!F13/Assumptions!F27 *-1 -> 593.83606 | G39: ='Income Statement'!G13/Assumptions!G27 *-1 -> 637.61108 | H39: ='Income Statement'!H13/Assumptions!H27 *-1 -> 693.07093 | I39: ='Income Statement'!I13/Assumptions!I27 *-1 -> 760.63546 | J39: ='Income Statement'!J13/Assumptions!J27 *-1 -> 826.07803 | K39: ='Income Statement'!K13/Assumptions!K27 *-1 -> 900.5531 | L39: ='Income Statement'!L13/Assumptions!L27 *-1 -> 982.70114
A40: Short-Term Provisions | B40: 196.51 | C40: 191.26 | D40: 387.47 | E40: =D40 -> 387.47 | F40: =E40 -> 387.47 | G40: =F40 -> 387.47 | H40: =G40 -> 387.47 | I40: =H40 -> 387.47 | J40: =I40 -> 387.47 | K40: =J40 -> 387.47 | L40: =K40 -> 387.47
A41: Current tax Liabilities | B41: 73.16 | C41: 47.78 | D41: 76.08 | E41: =D41 -> 76.08 | F41: =E41 -> 76.08 | G41: =F41 -> 76.08 | H41: =G41 -> 76.08 | I41: =H41 -> 76.08 | J41: =I41 -> 76.08 | K41: =J41 -> 76.08 | L41: =K41 -> 76.08
A42: Governmnet Grant | B42: 0.71 | C42: 0 | D42: 0 | E42: =D42 -> 0 | F42: =E42 -> 0 | G42: =F42 -> 0 | H42: =G42 -> 0 | I42: =H42 -> 0 | J42: =I42 -> 0 | K42: =J42 -> 0 | L42: =K42 -> 0
A43: Total Current Liabilities | B43: =SUM(B37:B42) -> 1851.41 | C43: =SUM(C37:C42) -> 2565.3 | D43: =SUM(D37:D42) -> 3614.27 | E43: =SUM(E37:E42) -> 3755.6022 | F43: =SUM(F37:F42) -> 3936.2943 | G43: =SUM(G37:G42) -> 4132.9556 | H43: =SUM(H37:H42) -> 4337.0818 | I43: =SUM(I37:I42) -> 4567.2766 | ... L43: =SUM(L37:L42) -> 5382.8559
A45: Long-Term Debt | B45: 61.92 | C45: 766.06 | D45: 747.75 | E45: =D45 -> 747.75 | F45: =E45 -> 747.75 | G45: =F45 -> 747.75 | H45: =G45 -> 747.75 | I45: =H45 -> 747.75 | J45: =I45 -> 747.75 | K45: =J45 -> 747.75 | L45: =K45 -> 747.75
A46: Deferred Tax Liabilities (Net) | B46: 3.87 | C46: 12.69 | D46: 8.69 | E46: =D46 -> 8.69 | F46: =E46 -> 8.69 | G46: =F46 -> 8.69 | H46: =G46 -> 8.69 | I46: =H46 -> 8.69 | J46: =I46 -> 8.69 | K46: =J46 -> 8.69 | L46: =K46 -> 8.69
...

Sheet CFS
A1: =Dashboard!A1 -> [Britannia LTD.]
A2: Cash Flow Statement
A3: (in INR Crores, unless otherwise stated)
A5: =Assumptions!A5 -> Particular | B5: =Assumptions!B5 -> FY2019 A | C5: =Assumptions!C5 -> FY2020 A | D5: =Assumptions!D5 -> FY2021 A | E5: =Assumptions!E5 -> FY2022 E | F5: =Assumptions!F5 -> FY2023 E | G5: =Assumptions!G5 -> FY2024 E | H5: =Assumptions!H5 -> FY2025 E | ... L5: =Assumptions!L5 -> FY2029 E
A6: Cash Flows From Operating Activities:
A7: Profit For The Year | B7: 1768.9 | C7: 1843.86 | D7: 2512.8 | E7: ='Income Statement'!E31 -> 2390.1465 | F7: ='Income Statement'!F31 -> 2665.4404 | G7: ='Income Statement'!G31 -> 2968.3133 | H7: ='Income Statement'!H31 -> 3132.7307 | I7: ='Income Statement'!I31 -> 3430.7242 | J7: ='Income Statement'!J31 -> 3735.06 | K7: ='Income Statement'!K31 -> 4034.6708 | L7: ='Income Statement'!L31 -> 4392.5966
A8: Adjustments To Reconcile Net Income To Cash Provided By Operating Activities | B8: 0 | C8: 0 | D8: 0
A9: Depreciation & Amortization | B9: 161.88 | C9: 184.81 | D9: 197.85 | E9: ='Income Statement'!E24*-1 -> 224.97421 | F9: ='Income Statement'!F24*-1 -> 236.31509 | G9: ='Income Statement'!G24*-1 -> 254.52266 | H9: ='Income Statement'!H24*-1 -> 278.34895 | I9: ='Income Statement'!I24*-1 -> 299.15394 | J9: ='Income Statement'!J24*-1 -> 324.0067 | K9: ='Income Statement'!K24*-1 -> 351.54263 | L9: ='Income Statement'!L24*-1 -> 380.3817
A10: Profit On Sale Of Assets (Including Assets Scrapped / Written Off) | B10: -0.97 | C10: -0.11 | D10: -0.33 | E10: 0 | F10: 0 | G10: 0 | H10: 0 | I10: 0 | J10: 0 | K10: 0 | L10: 0
A11: Profit On Sale Of Investments (Net) | B11: 0 | C11: 0 | D11: 0 | E11: 0 | F11: 0 | G11: 0 | H11: 0 | I11: 0 | J11: 0 | K11: 0 | L11: 0
A12: Provision For Doubtful Trade Receivables And Advances | B12: 0 | C12: 0 | D12: 0 | E12: 0 | F12: 0 | G12: 0 | H12: 0 | I12: 0 | J12: 0 | K12: 0 | L12: 0
A13: Share Of (Profit) / Loss Of Associate Companies (Net) | B13: 0 | C13: 0 | D13: 0 | E13: 0 | F13: 0 | G13: 0 | H13: 0 | I13: 0 | J13: 0 | K13: 0 | L13: 0
A14: Share Of Minority Interest | B14: 0 | C14: 0 | D14: 0 | E14: 0 | F14: 0 | G14: 0 | H14: 0 | I14: 0 | J14: 0 | K14: 0 | L14: 0
A15: Interest / Dividend (Net) | B15: -136.77 | C15: -176.77 | D15: -234.66 | E15: =-'Income Statement'!E27 -> -313 | F15: =-'Income Statement'!F27 -> -313 | G15: =-'Income Statement'!G27 -> -313 | H15: =-'Income Statement'!H27 -> -313 | I15: =-'Income Statement'!I27 -> -313 | J15: =-'Income Statement'!J27 -> -313 | K15: =-'Income Statement'!K27 -> -313 | L15: =-'Income Statement'!L27 -> -313
A16: Esop expense | B16: 0 | C16: 0 | D16: 0 | E16: 0 | F16: 0 | G16: 0 | H16: 0 | I16: 0 | J16: 0 | K16: 0 | L16: 0
A17: Net gain on financial asset measured | B17: -63.85 | C17: -89.88 | D17: -65.47 | E17: 0 | F17: 0 | G17: 0 | H17: 0 | I17: 0 | J17: 0 | K17: 0 | L17: 0
A18: Interest Income | B18: 0 | C18: 0 | D18: 0 | E18: 0 | F18: 0 | G18: 0 | H18: 0 | I18: 0 | J18: 0 | K18: 0 | L18: 0
A19: Finance cost | B19: 9.09 | C19: 76.9 | D19: 110.9 | E19: ='Income Statement'!E26*-1 -> 118.12345 | F19: ='Income Statement'!F26*-1 -> 111.67758 | G19: ='Income Statement'!G26*-1 -> 113.56701 | H19: ='Income Statement'!H26*-1 -> 114.45601 | I19: ='Income Statement'!I26*-1 -> 113.23354 | J19: ='Income Statement'!J26*-1 -> 113.75219 | K19: ='Income Statement'!K26*-1 -> 113.81391 | L19: ='Income Statement'!L26*-1 -> 113.59988
A20: Share Based Payment | B20: 16.12 | C20: 21.58 | D20: 18.94 | E20: 0 | F20: 0 | G20: 0 | H20: 0 | I20: 0 | J20: 0 | K20: 0 | L20: 0
A21: Other Adjustments 6 | B21: 0 | C21: 0 | D21: 0 | E21: 0 | F21: 0 | G21: 0 | H21: 0 | I21: 0 | J21: 0 | K21: 0 | L21: 0
A22: Adjustment for working capital | B22: 0 | C22: 0 | D22: 0
A23: Increase In Inventories | B23: -127.21 | C23: 42.99 | D23: -351.44 | E23: ='Balance Sheet'!D12-'Balance Sheet'!E12 -> 66.035983 | F23: ='Balance Sheet'!E12-'Balance Sheet'!F12 -> -97.255322 | G23: ='Balance Sheet'!F12-'Balance Sheet'!G12 -> -155.73812 | H23: ='Balance Sheet'!G12-'Balance Sheet'!H12 -> -72.636971 | I23: ='Balance Sheet'!H12-'Balance Sheet'!I12 -> -130.21376 | J23: ='Balance Sheet'!I12-'Balance Sheet'!J12 -> -143.53183 | K23: ='Balance Sheet'!J12-'Balance Sheet'!K12 -> -135.35102 | L23: ='Balance Sheet'!K12-'Balance Sheet'!L12 -> -162.26131
A24: (Increase) Decrease In Accounts Receivable | B24: -86.67 | C24: 78.85 | D24: 61.4 | E24: ='Balance Sheet'!D11-'Balance Sheet'!E11 -> -115.2642 | F24: ='Balance Sheet'!E11-'Balance Sheet'!F11 -> 0.055043801 | G24: ='Balance Sheet'!F11-'Balance Sheet'!G11 -> -15.929276 | H24: ='Balance Sheet'!G11-'Balance Sheet'!H11 -> -59.7218 | I24: ='Balance Sheet'!H11-'Balance Sheet'!I11 -> -29.019741 | J24: ='Balance Sheet'!I11-'Balance Sheet'!J11 -> -41.073693 | K24: ='Balance Sheet'!J11-'Balance Sheet'!K11 -> -52.396809 | L24: ='Balance Sheet'!K11-'Balance Sheet'!L11 -> -47.902265
A25: (Increase) Decrease In Finance Receivable | B25: 0 | C25: 0 | D25: 0 | E25: 0 | F25: 0 | G25: 0 | H25: 0 | I25: 0 | J25: 0 | K25: 0 | L25: 0
A26: Other Current And Non-Current Assets | B26: 10.9 | C26: -23.66 | D26: -170.82 | E26: ='Balance Sheet'!D14-'Balance Sheet'!E14 -> 0 | F26: ='Balance Sheet'!E14-'Balance Sheet'!F14 -> 0 | G26: ='Balance Sheet'!F14-'Balance Sheet'!G14 -> 0 | H26: ='Balance Sheet'!G14-'Balance Sheet'!H14 -> 0 | I26: ='Balance Sheet'!H14-'Balance Sheet'!I14 -> 0 | J26: ='Balance Sheet'!I14-'Balance Sheet'!J14 -> 0 | K26: ='Balance Sheet'!J14-'Balance Sheet'!K14 -> 0 | L26: ='Balance Sheet'!K14-'Balance Sheet'!L14 -> 0
