Workbook

Sheet Dashboard
A1: Infosys Ltd.
A2: Ratio Snapshot
A3: (In INR Crores, unless otherwise stated) | Blue = reported / hard-coded input, Black = formula, yellow cells = forecast
A5: COMPANY DETAILS | H5: DCF VALUATION SUMMARY
A6: Industry | B6: IT Services & Consulting | H6: Intrinsic value per share (Rs) | I6: =Valuation!B48 | L6: DCF value | M6: =Valuation!B48
A7: Sector | B7: Information Technology | H7: Current market price (Rs) | I7: =Valuation!B14 | L7: Market price | M7: =Valuation!B14
A8: Current Market Price (Rs) | B8: =Valuation!B14 | H8: Upside / (Downside) | I8: =Valuation!B50
A9: Market Capitalization (Rs crore) | B9: =Valuation!B15 | H9: WACC | I9: =Valuation!B11
A10: Year end | B10: FY2025 (31-Mar-2025) | H10: Long term growth | I10: =Valuation!B5
H11: Enterprise value (DCF, Rs crore) | I11: =Valuation!B42
A12: COMPANY DESCRIPTION | H12: Equity value (DCF, Rs crore) | I12: =Valuation!B46
A13: Infosys is one of the world's largest IT services and consulting companies. Founded in 1981 and headquartered in Bengaluru, it serves clients in 59 countries across financial services, retail, communication, energy & utilities, manufacturing, hi-tech and life sciences. FY2025 revenue was Rs 1,62,990 crore (US$19.3 bn) with an operating margin of 21.1%, a workforce of about 3.24 lakh people and no borrowings. Growth drivers: large-deal wins (US$11.6 bn TCV in FY25), cloud, data and generative AI (Infosys Topaz), and cost discipline through Project Maximus. Main risks: client discretionary spending, AI-led pricing deflation, wage inflation and rupee appreciation. | H13: Terminal value % of EV | I13: =Valuation!B53
H15: Check: balance sheet balances (sum of differences) | I15: =SUMPRODUCT(ABS('Balance Sheet'!B55:I55))+SUMPRODUCT(ABS(CFS!B39:I39)) | J15: =IF(I15=0,"OK","CHECK")
A24: Financial Year | B24: =Assumptions!E5 | C24: =Assumptions!F5 | D24: =Assumptions!G5 | E24: =Assumptions!H5 | F24: =Assumptions!I5
A26: Revenue | B26: ='Income Statement'!E7 | C26: ='Income Statement'!F7 | D26: ='Income Statement'!G7 | E26: ='Income Statement'!H7 | F26: ='Income Statement'!I7
A27: Operating Expenses (excl. D&A) | B27: =-'Income Statement'!E15 | C27: =-'Income Statement'!F15 | D27: =-'Income Statement'!G15 | E27: =-'Income Statement'!H15 | F27: =-'Income Statement'!I15
A28: EBITDA | B28: ='Income Statement'!E16 | C28: ='Income Statement'!F16 | D28: ='Income Statement'!G16 | E28: ='Income Statement'!H16 | F28: ='Income Statement'!I16
A29: EBITDA Margin (%) | B29: ='Income Statement'!E16/'Income Statement'!E7 | C29: ='Income Statement'!F16/'Income Statement'!F7 | D29: ='Income Statement'!G16/'Income Statement'!G7 | E29: ='Income Statement'!H16/'Income Statement'!H7 | F29: ='Income Statement'!I16/'Income Statement'!I7
A30: EBIT (Operating Profit) | B30: ='Income Statement'!E18 | C30: ='Income Statement'!F18 | D30: ='Income Statement'!G18 | E30: ='Income Statement'!H18 | F30: ='Income Statement'!I18
A31: EBIT Margin (%) | B31: ='Income Statement'!E18/'Income Statement'!E7 | C31: ='Income Statement'!F18/'Income Statement'!F7 | D31: ='Income Statement'!G18/'Income Statement'!G7 | E31: ='Income Statement'!H18/'Income Statement'!H7 | F31: ='Income Statement'!I18/'Income Statement'!I7
A32: Tax Expenses | B32: =-('Income Statement'!E22+'Income Statement'!E23) | C32: =-('Income Statement'!F22+'Income Statement'!F23) | D32: =-('Income Statement'!G22+'Income Statement'!G23) | E32: =-('Income Statement'!H22+'Income Statement'!H23) | F32: =-('Income Statement'!I22+'Income Statement'!I23)
A33: Profit After Tax | B33: ='Income Statement'!E24 | C33: ='Income Statement'!F24 | D33: ='Income Statement'!G24 | E33: ='Income Statement'!H24 | F33: ='Income Statement'!I24
A34: Net Margin (%) | B34: ='Income Statement'!E24/'Income Statement'!E7 | C34: ='Income Statement'!F24/'Income Statement'!F7 | D34: ='Income Statement'!G24/'Income Statement'!G7 | E34: ='Income Statement'!H24/'Income Statement'!H7 | F34: ='Income Statement'!I24/'Income Statement'!I7
A35: EPS (Rs) | B35: ='Income Statement'!E32 | C35: ='Income Statement'!F32 | D35: ='Income Statement'!G32 | E35: ='Income Statement'!H32 | F35: ='Income Statement'!I32
A36: Free Cash Flow | B36: =CFS!E41 | C36: =CFS!F41 | D36: =CFS!G41 | E36: =CFS!H41 | F36: =CFS!I41
A37: Cash | B37: ='Balance Sheet'!E8 | C37: ='Balance Sheet'!F8 | D37: ='Balance Sheet'!G8 | E37: ='Balance Sheet'!H8 | F37: ='Balance Sheet'!I8
A38: Cash + Investments | B38: ='Balance Sheet'!E8+'Balance Sheet'!E9+'Balance Sheet'!E22 | C38: ='Balance Sheet'!F8+'Balance Sheet'!F9+'Balance Sheet'!F22 | D38: ='Balance Sheet'!G8+'Balance Sheet'!G9+'Balance Sheet'!G22 | E38: ='Balance Sheet'!H8+'Balance Sheet'!H9+'Balance Sheet'!H22 | F38: ='Balance Sheet'!I8+'Balance Sheet'!I9+'Balance Sheet'!I22
A39: Return On Equity (%) | B39: ='Income Statement'!E24/'Balance Sheet'!E53 | C39: ='Income Statement'!F24/'Balance Sheet'!F53 | D39: ='Income Statement'!G24/'Balance Sheet'!G53 | E39: ='Income Statement'!H24/'Balance Sheet'!H53 | F39: ='Income Statement'!I24/'Balance Sheet'!I53
A40: Return on Capital Employed (%) | B40: ='Income Statement'!E18/('Balance Sheet'!E30-'Balance Sheet'!E39) | C40: ='Income Statement'!F18/('Balance Sheet'!F30-'Balance Sheet'!F39) | D40: ='Income Statement'!G18/('Balance Sheet'!G30-'Balance Sheet'!G39) | E40: ='Income Statement'!H18/('Balance Sheet'!H30-'Balance Sheet'!H39) | F40: ='Income Statement'!I18/('Balance Sheet'!I30-'Balance Sheet'!I39)
A42: Enterprise Value | B42: =B24 | C42: =C24 | D42: =D24 | E42: =E24 | F42: =F24
A43: Net Debt (lease liabilities less cash & investments) | B43: ='Balance Sheet'!E34+'Balance Sheet'!E41-('Balance Sheet'!E8+'Balance Sheet'!E9+'Balance Sheet'!E22) | C43: ='Balance Sheet'!F34+'Balance Sheet'!F41-('Balance Sheet'!F8+'Balance Sheet'!F9+'Balance Sheet'!F22) | D43: ='Balance Sheet'!G34+'Balance Sheet'!G41-('Balance Sheet'!G8+'Balance Sheet'!G9+'Balance Sheet'!G22) | E43: ='Balance Sheet'!H34+'Balance Sheet'!H41-('Balance Sheet'!H8+'Balance Sheet'!H9+'Balance Sheet'!H22) | F43: ='Balance Sheet'!I34+'Balance Sheet'!I41-('Balance Sheet'!I8+'Balance Sheet'!I9+'Balance Sheet'!I22)
A44: Market Capitalisation (at current price) | B44: =Valuation!$B$15 | C44: =Valuation!$B$15 | D44: =Valuation!$B$15 | E44: =Valuation!$B$15 | F44: =Valuation!$B$15
A45: Cash and Cash Equivalent | B45: ='Balance Sheet'!E8 | C45: ='Balance Sheet'!F8 | D45: ='Balance Sheet'!G8 | E45: ='Balance Sheet'!H8 | F45: ='Balance Sheet'!I8
A46: Enterprise Value (EV) | B46: =B43+B44 | C46: =C43+C44 | D46: =D43+D44 | E46: =E43+E44 | F46: =F43+F44

Sheet Company Overview
A1: Infosys Limited
A2: Ratio Snapshot
A3: (In INR Crores, unless otherwise stated) | Blue = reported / hard-coded input, Black = formula, yellow cells = forecast
A6: HIGHLIGHTS FROM INCOME STATEMENT | B6: =Assumptions!B5 | C6: =Assumptions!C5 | D6: =Assumptions!D5 | E6: =Assumptions!E5 | F6: =Assumptions!F5 | G6: =Assumptions!G5 | H6: =Assumptions!H5 | I6: =Assumptions!I5
A7: Revenue | B7: ='Income Statement'!B7 | C7: ='Income Statement'!C7 | D7: ='Income Statement'!D7 | E7: ='Income Statement'!E7 | F7: ='Income Statement'!F7 | G7: ='Income Statement'!G7 | H7: ='Income Statement'!H7 | I7: ='Income Statement'!I7
A8: EBITDA | B8: ='Income Statement'!B16 | C8: ='Income Statement'!C16 | D8: ='Income Statement'!D16 | E8: ='Income Statement'!E16 | F8: ='Income Statement'!F16 | G8: ='Income Statement'!G16 | H8: ='Income Statement'!H16 | I8: ='Income Statement'!I16
A9: EBIT | B9: ='Income Statement'!B18 | C9: ='Income Statement'!C18 | D9: ='Income Statement'!D18 | E9: ='Income Statement'!E18 | F9: ='Income Statement'!F18 | G9: ='Income Statement'!G18 | H9: ='Income Statement'!H18 | I9: ='Income Statement'!I18
A10: PBT | B10: ='Income Statement'!B21 | C10: ='Income Statement'!C21 | D10: ='Income Statement'!D21 | E10: ='Income Statement'!E21 | F10: ='Income Statement'!F21 | G10: ='Income Statement'!G21 | H10: ='Income Statement'!H21 | I10: ='Income Statement'!I21
A11: PAT | B11: ='Income Statement'!B24 | C11: ='Income Statement'!C24 | D11: ='Income Statement'!D24 | E11: ='Income Statement'!E24 | F11: ='Income Statement'!F24 | G11: ='Income Statement'!G24 | H11: ='Income Statement'!H24 | I11: ='Income Statement'!I24
A12: EPS (Rs) | B12: ='Income Statement'!B32 | C12: ='Income Statement'!C32 | D12: ='Income Statement'!D32 | E12: ='Income Statement'!E32 | F12: ='Income Statement'!F32 | G12: ='Income Statement'!G32 | H12: ='Income Statement'!H32 | I12: ='Income Statement'!I32
A14: HIGHLIGHTS FROM BALANCE SHEET | B14: =Assumptions!B5 | C14: =Assumptions!C5 | D14: =Assumptions!D5 | E14: =Assumptions!E5 | F14: =Assumptions!F5 | G14: =Assumptions!G5 | H14: =Assumptions!H5 | I14: =Assumptions!I5
A15: Fixed Assets (PPE + ROU + Intangibles) | B15: ='Balance Sheet'!B17+'Balance Sheet'!B18+'Balance Sheet'!B21 | C15: ='Balance Sheet'!C17+'Balance Sheet'!C18+'Balance Sheet'!C21 | D15: ='Balance Sheet'!D17+'Balance Sheet'!D18+'Balance Sheet'!D21 | E15: ='Balance Sheet'!E17+'Balance Sheet'!E18+'Balance Sheet'!E21 | F15: ='Balance Sheet'!F17+'Balance Sheet'!F18+'Balance Sheet'!F21 | G15: ='Balance Sheet'!G17+'Balance Sheet'!G18+'Balance Sheet'!G21 | H15: ='Balance Sheet'!H17+'Balance Sheet'!H18+'Balance Sheet'!H21 | I15: ='Balance Sheet'!I17+'Balance Sheet'!I18+'Balance Sheet'!I21
A16: Cash & Cash Equivalents | B16: ='Balance Sheet'!B8 | C16: ='Balance Sheet'!C8 | D16: ='Balance Sheet'!D8 | E16: ='Balance Sheet'!E8 | F16: ='Balance Sheet'!F8 | G16: ='Balance Sheet'!G8 | H16: ='Balance Sheet'!H8 | I16: ='Balance Sheet'!I8
A17: Cash + Investments | B17: ='Balance Sheet'!B8+'Balance Sheet'!B9+'Balance Sheet'!B22 | C17: ='Balance Sheet'!C8+'Balance Sheet'!C9+'Balance Sheet'!C22 | D17: ='Balance Sheet'!D8+'Balance Sheet'!D9+'Balance Sheet'!D22 | E17: ='Balance Sheet'!E8+'Balance Sheet'!E9+'Balance Sheet'!E22 | F17: ='Balance Sheet'!F8+'Balance Sheet'!F9+'Balance Sheet'!F22 | G17: ='Balance Sheet'!G8+'Balance Sheet'!G9+'Balance Sheet'!G22 | H17: ='Balance Sheet'!H8+'Balance Sheet'!H9+'Balance Sheet'!H22 | I17: ='Balance Sheet'!I8+'Balance Sheet'!I9+'Balance Sheet'!I22
A18: Working Capital (Current Assets - Current Liabilities) | B18: ='Balance Sheet'!B15-'Balance Sheet'!B39 | C18: ='Balance Sheet'!C15-'Balance Sheet'!C39 | D18: ='Balance Sheet'!D15-'Balance Sheet'!D39 | E18: ='Balance Sheet'!E15-'Balance Sheet'!E39 | F18: ='Balance Sheet'!F15-'Balance Sheet'!F39 | G18: ='Balance Sheet'!G15-'Balance Sheet'!G39 | H18: ='Balance Sheet'!H15-'Balance Sheet'!H39 | I18: ='Balance Sheet'!I15-'Balance Sheet'!I39
A19: Lease Liabilities | B19: ='Balance Sheet'!B34+'Balance Sheet'!B41 | C19: ='Balance Sheet'!C34+'Balance Sheet'!C41 | D19: ='Balance Sheet'!D34+'Balance Sheet'!D41 | E19: ='Balance Sheet'!E34+'Balance Sheet'!E41 | F19: ='Balance Sheet'!F34+'Balance Sheet'!F41 | G19: ='Balance Sheet'!G34+'Balance Sheet'!G41 | H19: ='Balance Sheet'!H34+'Balance Sheet'!H41 | I19: ='Balance Sheet'!I34+'Balance Sheet'!I41
A20: Equity (Share Capital) | B20: ='Balance Sheet'!B49 | C20: ='Balance Sheet'!C49 | D20: ='Balance Sheet'!D49 | E20: ='Balance Sheet'!E49 | F20: ='Balance Sheet'!F49 | G20: ='Balance Sheet'!G49 | H20: ='Balance Sheet'!H49 | I20: ='Balance Sheet'!I49
A21: Shareholders' Funds (Reserves) | B21: ='Balance Sheet'!B50 | C21: ='Balance Sheet'!C50 | D21: ='Balance Sheet'!D50 | E21: ='Balance Sheet'!E50 | F21: ='Balance Sheet'!F50 | G21: ='Balance Sheet'!G50 | H21: ='Balance Sheet'!H50 | I21: ='Balance Sheet'!I50
A23: GROWTH | B23: =Assumptions!B5 | C23: =Assumptions!C5 | D23: =Assumptions!D5 | E23: =Assumptions!E5 | F23: =Assumptions!F5 | G23: =Assumptions!G5 | H23: =Assumptions!H5 | I23: =Assumptions!I5
A24: Revenue Growth y-o-y | C24: ='Income Statement'!C7/'Income Statement'!B7-1 | D24: ='Income Statement'!D7/'Income Statement'!C7-1 | E24: ='Income Statement'!E7/'Income Statement'!D7-1 | F24: ='Income Statement'!F7/'Income Statement'!E7-1 | G24: ='Income Statement'!G7/'Income Statement'!F7-1 | H24: ='Income Statement'!H7/'Income Statement'!G7-1 | I24: ='Income Statement'!I7/'Income Statement'!H7-1
A25: EBIT Growth y-o-y | C25: ='Income Statement'!C18/'Income Statement'!B18-1 | D25: ='Income Statement'!D18/'Income Statement'!C18-1 | E25: ='Income Statement'!E18/'Income Statement'!D18-1 | F25: ='Income Statement'!F18/'Income Statement'!E18-1 | G25: ='Income Statement'!G18/'Income Statement'!F18-1 | H25: ='Income Statement'!H18/'Income Statement'!G18-1 | I25: ='Income Statement'!I18/'Income Statement'!H18-1
A26: PAT Growth y-o-y | C26: ='Income Statement'!C24/'Income Statement'!B24-1 | D26: ='Income Statement'!D24/'Income Statement'!C24-1 | E26: ='Income Statement'!E24/'Income Statement'!D24-1 | F26: ='Income Statement'!F24/'Income Statement'!E24-1 | G26: ='Income Statement'!G24/'Income Statement'!F24-1 | H26: ='Income Statement'!H24/'Income Statement'!G24-1 | I26: ='Income Statement'!I24/'Income Statement'!H24-1
A28: MARGINS | B28: =Assumptions!B5 | C28: =Assumptions!C5 | D28: =Assumptions!D5 | E28: =Assumptions!E5 | F28: =Assumptions!F5 | G28: =Assumptions!G5 | H28: =Assumptions!H5 | I28: =Assumptions!I5
A29: EBITDA Margin (%) | B29: ='Income Statement'!B16/'Income Statement'!B7 | C29: ='Income Statement'!C16/'Income Statement'!C7 | D29: ='Income Statement'!D16/'Income Statement'!D7 | E29: ='Income Statement'!E16/'Income Statement'!E7 | F29: ='Income Statement'!F16/'Income Statement'!F7 | G29: ='Income Statement'!G16/'Income Statement'!G7 | H29: ='Income Statement'!H16/'Income Statement'!H7 | I29: ='Income Statement'!I16/'Income Statement'!I7
A30: EBIT Margin (%) | B30: ='Income Statement'!B18/'Income Statement'!B7 | C30: ='Income Statement'!C18/'Income Statement'!C7 | D30: ='Income Statement'!D18/'Income Statement'!D7 | E30: ='Income Statement'!E18/'Income Statement'!E7 | F30: ='Income Statement'!F18/'Income Statement'!F7 | G30: ='Income Statement'!G18/'Income Statement'!G7 | H30: ='Income Statement'!H18/'Income Statement'!H7 | I30: ='Income Statement'!I18/'Income Statement'!I7
A31: Pre-Tax Margin (%) | B31: ='Income Statement'!B21/'Income Statement'!B7 | C31: ='Income Statement'!C21/'Income Statement'!C7 | D31: ='Income Statement'!D21/'Income Statement'!D7 | E31: ='Income Statement'!E21/'Income Statement'!E7 | F31: ='Income Statement'!F21/'Income Statement'!F7 | G31: ='Income Statement'!G21/'Income Statement'!G7 | H31: ='Income Statement'!H21/'Income Statement'!H7 | I31: ='Income Statement'!I21/'Income Statement'!I7
A32: PAT Margin (%) | B32: ='Income Statement'!B24/'Income Statement'!B7 | C32: ='Income Statement'!C24/'Income Statement'!C7 | D32: ='Income Statement'!D24/'Income Statement'!D7 | E32: ='Income Statement'!E24/'Income Statement'!E7 | F32: ='Income Statement'!F24/'Income Statement'!F7 | G32: ='Income Statement'!G24/'Income Statement'!G7 | H32: ='Income Statement'!H24/'Income Statement'!H7 | I32: ='Income Statement'!I24/'Income Statement'!I7
A34: EXPENDITURE RATIOS | B34: =Assumptions!B5 | C34: =Assumptions!C5 | D34: =Assumptions!D5 | E34: =Assumptions!E5 | F34: =Assumptions!F5 | G34: =Assumptions!G5 | H34: =Assumptions!H5 | I34: =Assumptions!I5
A35: Employee Expenses as % of Revenue | B35: ='Income Statement'!B8/'Income Statement'!B7 | C35: ='Income Statement'!C8/'Income Statement'!C7 | D35: ='Income Statement'!D8/'Income Statement'!D7 | E35: ='Income Statement'!E8/'Income Statement'!E7 | F35: ='Income Statement'!F8/'Income Statement'!F7 | G35: ='Income Statement'!G8/'Income Statement'!G7 | H35: ='Income Statement'!H8/'Income Statement'!H7 | I35: ='Income Statement'!I8/'Income Statement'!I7
A36: Sub-contractor Expenses as % of Revenue | B36: ='Income Statement'!B9/'Income Statement'!B7 | C36: ='Income Statement'!C9/'Income Statement'!C7 | D36: ='Income Statement'!D9/'Income Statement'!D7 | E36: ='Income Statement'!E9/'Income Statement'!E7 | F36: ='Income Statement'!F9/'Income Statement'!F7 | G36: ='Income Statement'!G9/'Income Statement'!G7 | H36: ='Income Statement'!H9/'Income Statement'!H7 | I36: ='Income Statement'!I9/'Income Statement'!I7
A37: Software Packages and Others as % of Revenue | B37: ='Income Statement'!B11/'Income Statement'!B7 | C37: ='Income Statement'!C11/'Income Statement'!C7 | D37: ='Income Statement'!D11/'Income Statement'!D7 | E37: ='Income Statement'!E11/'Income Statement'!E7 | F37: ='Income Statement'!F11/'Income Statement'!F7 | G37: ='Income Statement'!G11/'Income Statement'!G7 | H37: ='Income Statement'!H11/'Income Statement'!H7 | I37: ='Income Statement'!I11/'Income Statement'!I7
A39: RETURNS | B39: =Assumptions!B5 | C39: =Assumptions!C5 | D39: =Assumptions!D5 | E39: =Assumptions!E5 | F39: =Assumptions!F5 | G39: =Assumptions!G5 | H39: =Assumptions!H5 | I39: =Assumptions!I5
A40: Return on Capital Employed (%) = EBIT / (Total assets - Current liabilities) | B40: ='Income Statement'!B18/('Balance Sheet'!B30-'Balance Sheet'!B39) | C40: ='Income Statement'!C18/('Balance Sheet'!C30-'Balance Sheet'!C39) | D40: ='Income Statement'!D18/('Balance Sheet'!D30-'Balance Sheet'!D39) | E40: ='Income Statement'!E18/('Balance Sheet'!E30-'Balance Sheet'!E39) | F40: ='Income Statement'!F18/('Balance Sheet'!F30-'Balance Sheet'!F39) | G40: ='Income Statement'!G18/('Balance Sheet'!G30-'Balance Sheet'!G39) | H40: ='Income Statement'!H18/('Balance Sheet'!H30-'Balance Sheet'!H39) | I40: ='Income Statement'!I18/('Balance Sheet'!I30-'Balance Sheet'!I39)
A41: Return on Assets (%) = PAT / Total assets | B41: ='Income Statement'!B24/'Balance Sheet'!B30 | C41: ='Income Statement'!C24/'Balance Sheet'!C30 | D41: ='Income Statement'!D24/'Balance Sheet'!D30 | E41: ='Income Statement'!E24/'Balance Sheet'!E30 | F41: ='Income Statement'!F24/'Balance Sheet'!F30 | G41: ='Income Statement'!G24/'Balance Sheet'!G30 | H41: ='Income Statement'!H24/'Balance Sheet'!H30 | I41: ='Income Statement'!I24/'Balance Sheet'!I30
A42: Return On Equity (%) = PAT / Total equity | B42: ='Income Statement'!B24/'Balance Sheet'!B53 | C42: ='Income Statement'!C24/'Balance Sheet'!C53 | D42: ='Income Statement'!D24/'Balance Sheet'!D53 | E42: ='Income Statement'!E24/'Balance Sheet'!E53 | F42: ='Income Statement'!F24/'Balance Sheet'!F53 | G42: ='Income Statement'!G24/'Balance Sheet'!G53 | H42: ='Income Statement'!H24/'Balance Sheet'!H53 | I42: ='Income Statement'!I24/'Balance Sheet'!I53
A44: DuPONT ANALYSIS | B44: =Assumptions!B5 | C44: =Assumptions!C5 | D44: =Assumptions!D5 | E44: =Assumptions!E5 | F44: =Assumptions!F5 | G44: =Assumptions!G5 | H44: =Assumptions!H5 | I44: =Assumptions!I5
A45: PAT Margin (%) | B45: ='Income Statement'!B24/'Income Statement'!B7 | C45: ='Income Statement'!C24/'Income Statement'!C7 | D45: ='Income Statement'!D24/'Income Statement'!D7 | E45: ='Income Statement'!E24/'Income Statement'!E7 | F45: ='Income Statement'!F24/'Income Statement'!F7 | G45: ='Income Statement'!G24/'Income Statement'!G7 | H45: ='Income Statement'!H24/'Income Statement'!H7 | I45: ='Income Statement'!I24/'Income Statement'!I7
A46: Asset Turnover (x) | B46: ='Income Statement'!B7/'Balance Sheet'!B30 | C46: ='Income Statement'!C7/'Balance Sheet'!C30 | D46: ='Income Statement'!D7/'Balance Sheet'!D30 | E46: ='Income Statement'!E7/'Balance Sheet'!E30 | F46: ='Income Statement'!F7/'Balance Sheet'!F30 | G46: ='Income Statement'!G7/'Balance Sheet'!G30 | H46: ='Income Statement'!H7/'Balance Sheet'!H30 | I46: ='Income Statement'!I7/'Balance Sheet'!I30
A47: Financial Leverage (Total assets / Equity) | B47: ='Balance Sheet'!B30/'Balance Sheet'!B53 | C47: ='Balance Sheet'!C30/'Balance Sheet'!C53 | D47: ='Balance Sheet'!D30/'Balance Sheet'!D53 | E47: ='Balance Sheet'!E30/'Balance Sheet'!E53 | F47: ='Balance Sheet'!F30/'Balance Sheet'!F53 | G47: ='Balance Sheet'!G30/'Balance Sheet'!G53 | H47: ='Balance Sheet'!H30/'Balance Sheet'!H53 | I47: ='Balance Sheet'!I30/'Balance Sheet'!I53
A48: Return On Equity (%) | B48: ='Income Statement'!B24/'Balance Sheet'!B53 | C48: ='Income Statement'!C24/'Balance Sheet'!C53 | D48: ='Income Statement'!D24/'Balance Sheet'!D53 | E48: ='Income Statement'!E24/'Balance Sheet'!E53 | F48: ='Income Statement'!F24/'Balance Sheet'!F53 | G48: ='Income Statement'!G24/'Balance Sheet'!G53 | H48: ='Income Statement'!H24/'Balance Sheet'!H53 | I48: ='Income Statement'!I24/'Balance Sheet'!I53
...

Sheet Assumptions
A1: Infosys Limited
A2: Assumptions
A3: (In INR Crores, unless otherwise stated) | Blue = reported / hard-coded input, Black = formula, yellow cells = forecast
A5: Particular | B5: FY2023 A | C5: FY2024 A | D5: FY2025 A | E5: FY2026 E | F5: FY2027 E | G5: FY2028 E | H5: FY2029 E | I5: FY2030 E
A6: Income Statement
A7: Revenue Growth | C7: ='Income Statement'!C7/'Income Statement'!B7-1 | D7: ='Income Statement'!D7/'Income Statement'!C7-1 | E7: 0.045 | F7: 0.07 | G7: 0.08 | H7: 0.08 | I7: 0.08 | K7: Input (INR). FY26E ~US$ growth 2% (mgmt guidance 0-3% cc) + ~2% INR depreciation; then 5-6% US$ growth + 1.5-2% INR.
A8: Employee benefit expenses (% of revenue) | B8: ='Income Statement'!B8/'Income Statement'!B7 | C8: ='Income Statement'!C8/'Income Statement'!C7 | D8: ='Income Statement'!D8/'Income Statement'!D7 | E8: =AVERAGE(B8:D8) | F8: =AVERAGE(C8:E8) | G8: =AVERAGE(D8:F8) | H8: =AVERAGE(E8:G8) | I8: =AVERAGE(F8:H8) | K8: Forecast = average of previous 3 years
A9: Cost of technical sub-contractors (% of revenue) | B9: ='Income Statement'!B9/'Income Statement'!B7 | C9: ='Income Statement'!C9/'Income Statement'!C7 | D9: ='Income Statement'!D9/'Income Statement'!D7 | E9: =AVERAGE(B9:D9) | F9: =AVERAGE(C9:E9) | G9: =AVERAGE(D9:F9) | H9: =AVERAGE(E9:G9) | I9: =AVERAGE(F9:H9)
A10: Travel expenses (% of revenue) | B10: ='Income Statement'!B10/'Income Statement'!B7 | C10: ='Income Statement'!C10/'Income Statement'!C7 | D10: ='Income Statement'!D10/'Income Statement'!D7 | E10: =AVERAGE(B10:D10) | F10: =AVERAGE(C10:E10) | G10: =AVERAGE(D10:F10) | H10: =AVERAGE(E10:G10) | I10: =AVERAGE(F10:H10)
A11: Cost of software packages and others (% of revenue) | B11: ='Income Statement'!B11/'Income Statement'!B7 | C11: ='Income Statement'!C11/'Income Statement'!C7 | D11: ='Income Statement'!D11/'Income Statement'!D7 | E11: =AVERAGE(B11:D11) | F11: =AVERAGE(C11:E11) | G11: =AVERAGE(D11:F11) | H11: =AVERAGE(E11:G11) | I11: =AVERAGE(F11:H11)
A12: Communication expenses (% of revenue) | B12: ='Income Statement'!B12/'Income Statement'!B7 | C12: ='Income Statement'!C12/'Income Statement'!C7 | D12: ='Income Statement'!D12/'Income Statement'!D7 | E12: =AVERAGE(B12:D12) | F12: =AVERAGE(C12:E12) | G12: =AVERAGE(D12:F12) | H12: =AVERAGE(E12:G12) | I12: =AVERAGE(F12:H12)
A13: Consultancy and professional charges (% of revenue) | B13: ='Income Statement'!B13/'Income Statement'!B7 | C13: ='Income Statement'!C13/'Income Statement'!C7 | D13: ='Income Statement'!D13/'Income Statement'!D7 | E13: =AVERAGE(B13:D13) | F13: =AVERAGE(C13:E13) | G13: =AVERAGE(D13:F13) | H13: =AVERAGE(E13:G13) | I13: =AVERAGE(F13:H13)
A14: Other expenses (% of revenue) | B14: ='Income Statement'!B14/'Income Statement'!B7 | C14: ='Income Statement'!C14/'Income Statement'!C7 | D14: ='Income Statement'!D14/'Income Statement'!D7 | E14: =AVERAGE(B14:D14) | F14: =AVERAGE(C14:E14) | G14: =AVERAGE(D14:F14) | H14: =AVERAGE(E14:G14) | I14: =AVERAGE(F14:H14)
A15: Effective tax rate (tax / PBT) | B15: =('Income Statement'!B22+'Income Statement'!B23)/'Income Statement'!B21 | C15: =('Income Statement'!C22+'Income Statement'!C23)/'Income Statement'!C21 | D15: =('Income Statement'!D22+'Income Statement'!D23)/'Income Statement'!D21 | E15: =AVERAGE(B15:D15) | F15: =AVERAGE(C15:E15) | G15: =AVERAGE(D15:F15) | H15: =AVERAGE(E15:G15) | I15: =AVERAGE(F15:H15)
A16: Other income, net (Rs crore) | B16: ='Income Statement'!B19 | C16: ='Income Statement'!C19 | D16: ='Income Statement'!D19 | E16: =AVERAGE(B16:D16) | F16: =AVERAGE(C16:E16) | G16: =AVERAGE(D16:F16) | H16: =AVERAGE(E16:G16) | I16: =AVERAGE(F16:H16) | K16: Forecast = average of previous 3 years (interest on cash pile + treasury gains)
A17: Finance cost / opening lease liabilities | C17: ='Income Statement'!C20/('Balance Sheet'!B34+'Balance Sheet'!B41) | D17: ='Income Statement'!D20/('Balance Sheet'!C34+'Balance Sheet'!C41) | E17: =AVERAGE(C17:D17) | F17: =AVERAGE(D17:E17) | G17: =AVERAGE(E17:F17) | H17: =AVERAGE(F17:G17) | I17: =AVERAGE(G17:H17) | K17: Infosys has no borrowings; finance cost is almost all lease interest
A19: Balance Sheet
A20: Accounts Receivable Turnover (Revenue / Trade receivables) | B20: ='Income Statement'!B7/'Balance Sheet'!B10 | C20: ='Income Statement'!C7/'Balance Sheet'!C10 | D20: ='Income Statement'!D7/'Balance Sheet'!D10 | E20: =AVERAGE(B20:D20) | F20: =AVERAGE(C20:E20) | G20: =AVERAGE(D20:F20) | H20: =AVERAGE(E20:G20) | I20: =AVERAGE(F20:H20) | K20: Forecast = average of previous 3 years
A21: Other financial assets (current) Turnover | B21: ='Income Statement'!B7/'Balance Sheet'!B12 | C21: ='Income Statement'!C7/'Balance Sheet'!C12 | D21: ='Income Statement'!D7/'Balance Sheet'!D12 | E21: =AVERAGE(B21:D21) | F21: =AVERAGE(C21:E21) | G21: =AVERAGE(D21:F21) | H21: =AVERAGE(E21:G21) | I21: =AVERAGE(F21:H21)
A22: Other current assets Turnover | B22: ='Income Statement'!B7/'Balance Sheet'!B14 | C22: ='Income Statement'!C7/'Balance Sheet'!C14 | D22: ='Income Statement'!D7/'Balance Sheet'!D14 | E22: =AVERAGE(B22:D22) | F22: =AVERAGE(C22:E22) | G22: =AVERAGE(D22:F22) | H22: =AVERAGE(E22:G22) | I22: =AVERAGE(F22:H22)
A23: Accounts Payable Turnover (Revenue / Trade payables) | B23: ='Income Statement'!B7/'Balance Sheet'!B33 | C23: ='Income Statement'!C7/'Balance Sheet'!C33 | D23: ='Income Statement'!D7/'Balance Sheet'!D33 | E23: =AVERAGE(B23:D23) | F23: =AVERAGE(C23:E23) | G23: =AVERAGE(D23:F23) | H23: =AVERAGE(E23:G23) | I23: =AVERAGE(F23:H23)
A24: Other financial liabilities (current) Turnover | B24: ='Income Statement'!B7/'Balance Sheet'!B35 | C24: ='Income Statement'!C7/'Balance Sheet'!C35 | D24: ='Income Statement'!D7/'Balance Sheet'!D35 | E24: =AVERAGE(B24:D24) | F24: =AVERAGE(C24:E24) | G24: =AVERAGE(D24:F24) | H24: =AVERAGE(E24:G24) | I24: =AVERAGE(F24:H24)
A25: Other current liabilities Turnover | B25: ='Income Statement'!B7/'Balance Sheet'!B36 | C25: ='Income Statement'!C7/'Balance Sheet'!C36 | D25: ='Income Statement'!D7/'Balance Sheet'!D36 | E25: =AVERAGE(B25:D25) | F25: =AVERAGE(C25:E25) | G25: =AVERAGE(D25:F25) | H25: =AVERAGE(E25:G25) | I25: =AVERAGE(F25:H25)
A26: Provisions Turnover | B26: ='Income Statement'!B7/'Balance Sheet'!B37 | C26: ='Income Statement'!C7/'Balance Sheet'!C37 | D26: ='Income Statement'!D7/'Balance Sheet'!D37 | E26: =AVERAGE(B26:D26) | F26: =AVERAGE(C26:E26) | G26: =AVERAGE(D26:F26) | H26: =AVERAGE(E26:G26) | I26: =AVERAGE(F26:H26)
A27: Dividend payout ratio (% of owners PAT) | B27: ='Income Statement'!B34/'Income Statement'!B26 | C27: ='Income Statement'!C34/'Income Statement'!C26 | D27: ='Income Statement'!D34/'Income Statement'!D26 | E27: 0.7 | F27: 0.7 | G27: 0.7 | H27: 0.7 | I27: 0.7 | K27: Input. Policy: ~85% of free cash flow returned over 5 years (FY25 payout incl. Rs8 special dividend)
A28: Current portion of lease liabilities (%) | B28: ='Balance Sheet'!B34/('Balance Sheet'!B34+'Balance Sheet'!B41) | C28: ='Balance Sheet'!C34/('Balance Sheet'!C34+'Balance Sheet'!C41) | D28: ='Balance Sheet'!D34/('Balance Sheet'!D34+'Balance Sheet'!D41) | E28: =D28 | F28: =E28 | G28: =F28 | H28: =G28 | I28: =H28
A30: Capex, Depreciation and Leases
A31: Capex (PPE + intangibles) as % of revenue | B31: =-CFS!B22/'Income Statement'!B7 | C31: =-CFS!C22/'Income Statement'!C7 | D31: =-CFS!D22/'Income Statement'!D7 | E31: =AVERAGE(B31:D31) | F31: =AVERAGE(C31:E31) | G31: =AVERAGE(D31:F31) | H31: =AVERAGE(E31:G31) | I31: =AVERAGE(F31:H31)
A32: PPE share of capex | E32: 0.95 | F32: 0.95 | G32: 0.95 | H32: 0.95 | I32: 0.95 | K32: Input: remainder goes to intangibles (software)
A33: New leases (right-of-use additions) as % of revenue | C33: =Assumptions!C47/'Income Statement'!C7 | D33: =Assumptions!D47/'Income Statement'!D7 | E33: =AVERAGE(C33:D33) | F33: =AVERAGE(D33:E33) | G33: =AVERAGE(E33:F33) | H33: =AVERAGE(F33:G33) | I33: =AVERAGE(G33:H33)
A34: D&A as % of opening net block (PPE + ROU + intangibles) | C34: ='Income Statement'!C17/('Balance Sheet'!B17+'Balance Sheet'!B18+'Balance Sheet'!B21) | D34: ='Income Statement'!D17/('Balance Sheet'!C17+'Balance Sheet'!C18+'Balance Sheet'!C21) | E34: =AVERAGE(C34:D34) | F34: =AVERAGE(D34:E34) | G34: =AVERAGE(E34:F34) | H34: =AVERAGE(F34:G34) | I34: =AVERAGE(G34:H34)
A35: Lease payments (principal + interest) / opening lease liabilities | C35: =-CFS!C29/('Balance Sheet'!B34+'Balance Sheet'!B41) | D35: =-CFS!D29/('Balance Sheet'!C34+'Balance Sheet'!C41) | E35: =AVERAGE(C35:D35) | F35: =AVERAGE(D35:E35) | G35: =AVERAGE(E35:F35) | H35: =AVERAGE(F35:G35) | I35: =AVERAGE(G35:H35)
A38: ASSET SCHEDULE
A39: Property, Plant & Equipment
A40: Net block (Opening) | E40: =D43 | F40: =E43 | G40: =F43 | H40: =G43 | I40: =H43
A41: + Capex on PPE | E41: ='Income Statement'!E7*E31*E32 | F41: ='Income Statement'!F7*F31*F32 | G41: ='Income Statement'!G7*G31*G32 | H41: ='Income Statement'!H7*H31*H32 | I41: ='Income Statement'!I7*I31*I32
A42: - Depreciation | E42: =E34*E40 | F42: =F34*F40 | G42: =G34*G40 | H42: =H34*H40 | I42: =I34*I40
A43: Net block (Closing) | B43: ='Balance Sheet'!B17 | C43: ='Balance Sheet'!C17 | D43: ='Balance Sheet'!D17 | E43: =E40+E41-E42 | F43: =F40+F41-F42 | G43: =G40+G41-G42 | H43: =H40+H41-H42 | I43: =I40+I41-I42
A45: Right-of-use assets (leases)
A46: Net block (Opening) | E46: =D49 | F46: =E49 | G46: =F49 | H46: =G49 | I46: =H49
...

Sheet Income Statement
A1: Infosys Limited
A2: INCOME STATEMENTS
A3: (In INR Crores, unless otherwise stated) | Blue = reported / hard-coded input, Black = formula, yellow cells = forecast
A5: Particulars | B5: =Assumptions!B5 | C5: =Assumptions!C5 | D5: =Assumptions!D5 | E5: =Assumptions!E5 | F5: =Assumptions!F5 | G5: =Assumptions!G5 | H5: =Assumptions!H5 | I5: =Assumptions!I5
A7: Revenue from Operations | B7: 146767 | C7: 153670 | D7: 162990 | E7: =D7*(1+Assumptions!E7) | F7: =E7*(1+Assumptions!F7) | G7: =F7*(1+Assumptions!G7) | H7: =G7*(1+Assumptions!H7) | I7: =H7*(1+Assumptions!I7)
A8: Employee benefit expenses | B8: 78359 | C8: 82620 | D8: 85950 | E8: =E$7*Assumptions!E8 | F8: =F$7*Assumptions!F8 | G8: =G$7*Assumptions!G8 | H8: =H$7*Assumptions!H8 | I8: =I$7*Assumptions!I8
A9: Cost of technical sub-contractors | B9: 14062 | C9: 12232 | D9: 12937 | E9: =E$7*Assumptions!E9 | F9: =F$7*Assumptions!F9 | G9: =G$7*Assumptions!G9 | H9: =H$7*Assumptions!H9 | I9: =I$7*Assumptions!I9
A10: Travel expenses | B10: 1525 | C10: 1759 | D10: 1894 | E10: =E$7*Assumptions!E10 | F10: =F$7*Assumptions!F10 | G10: =G$7*Assumptions!G10 | H10: =H$7*Assumptions!H10 | I10: =I$7*Assumptions!I10
A11: Cost of software packages and others | B11: 10902 | C11: 13515 | D11: 15911 | E11: =E$7*Assumptions!E11 | F11: =F$7*Assumptions!F11 | G11: =G$7*Assumptions!G11 | H11: =H$7*Assumptions!H11 | I11: =I$7*Assumptions!I11
A12: Communication expenses | B12: 713 | C12: 677 | D12: 620 | E12: =E$7*Assumptions!E12 | F12: =F$7*Assumptions!F12 | G12: =G$7*Assumptions!G12 | H12: =H$7*Assumptions!H12 | I12: =I$7*Assumptions!I12
A13: Consultancy and professional charges | B13: 1684 | C13: 1726 | D13: 1655 | E13: =E$7*Assumptions!E13 | F13: =F$7*Assumptions!F13 | G13: =G$7*Assumptions!G13 | H13: =H$7*Assumptions!H13 | I13: =I$7*Assumptions!I13
A14: Other expenses | B14: 4392 | C14: 4716 | D14: 4787 | E14: =E$7*Assumptions!E14 | F14: =F$7*Assumptions!F14 | G14: =G$7*Assumptions!G14 | H14: =H$7*Assumptions!H14 | I14: =I$7*Assumptions!I14
A15: Total Operating Expenditure | B15: =SUM(B8:B14) | C15: =SUM(C8:C14) | D15: =SUM(D8:D14) | E15: =SUM(E8:E14) | F15: =SUM(F8:F14) | G15: =SUM(G8:G14) | H15: =SUM(H8:H14) | I15: =SUM(I8:I14)
A16: EBITDA | B16: =B7-B15 | C16: =C7-C15 | D16: =D7-D15 | E16: =E7-E15 | F16: =F7-F15 | G16: =G7-G15 | H16: =H7-H15 | I16: =I7-I15
A17: Depreciation & Amortisation | B17: 4225 | C17: 4678 | D17: 4812 | E17: =Assumptions!E57 | F17: =Assumptions!F57 | G17: =Assumptions!G57 | H17: =Assumptions!H57 | I17: =Assumptions!I57
A18: EBIT (Operating Profit) | B18: =B16-B17 | C18: =C16-C17 | D18: =D16-D17 | E18: =E16-E17 | F18: =F16-F17 | G18: =G16-G17 | H18: =H16-H17 | I18: =I16-I17
A19: Other Income, net | B19: 2701 | C19: 4711 | D19: 3600 | E19: =Assumptions!E16 | F19: =Assumptions!F16 | G19: =Assumptions!G16 | H19: =Assumptions!H16 | I19: =Assumptions!I16
A20: Finance Cost (lease interest) | B20: 284 | C20: 470 | D20: 416 | E20: =Assumptions!E62 | F20: =Assumptions!F62 | G20: =Assumptions!G62 | H20: =Assumptions!H62 | I20: =Assumptions!I62
A21: Profit before Tax | B21: =B18+B19-B20 | C21: =C18+C19-C20 | D21: =D18+D19-D20 | E21: =E18+E19-E20 | F21: =F18+F19-F20 | G21: =G18+G19-G20 | H21: =H18+H19-H20 | I21: =I18+I19-I20
A22: Current Tax | B22: 9287 | C22: 8390 | D22: 12130 | E22: =E21*Assumptions!E15 | F22: =F21*Assumptions!F15 | G22: =G21*Assumptions!G15 | H22: =H21*Assumptions!H15 | I22: =I21*Assumptions!I15
A23: Deferred Tax | B23: -73 | C23: 1350 | D23: -1272 | E23: 0 | F23: 0 | G23: 0 | H23: 0 | I23: 0
A24: Profit after Tax | B24: =B21-B22-B23 | C24: =C21-C22-C23 | D24: =D21-D22-D23 | E24: =E21-E22-E23 | F24: =F21-F22-F23 | G24: =G21-G22-G23 | H24: =H21-H22-H23 | I24: =I21-I22-I23
A25: Minority Interests | B25: 13 | C25: 15 | D25: 37 | E25: =AVERAGE(B25:D25) | F25: =AVERAGE(C25:E25) | G25: =AVERAGE(D25:F25) | H25: =AVERAGE(E25:G25) | I25: =AVERAGE(F25:H25)
A26: Profit attributable to owners of the Company | B26: =B24-B25 | C26: =C24-C25 | D26: =D24-D25 | E26: =E24-E25 | F26: =F24-F25 | G26: =G24-G25 | H26: =H24-H25 | I26: =I24-I25
A27: Other Comprehensive Income | B27: 514 | C27: 520 | D27: 459 | E27: 0 | F27: 0 | G27: 0 | H27: 0 | I27: 0
A28: Total Comprehensive Income | B28: =B24+B27 | C28: =C24+C27 | D28: =D24+D27 | E28: =E24+E27 | F28: =F24+F27 | G28: =G24+G27 | H28: =H24+H27 | I28: =I24+I27
A29: Number of Shares Issued (crore):
A30: Basic | B30: 418.09 | C30: 413.857 | D30: 414.161 | E30: =D30 | F30: =E30 | G30: =F30 | H30: =G30 | I30: =H30
A31: Diluted | B31: 418.773 | C31: 414.468 | D31: 415.205 | E31: =D31 | F31: =E31 | G31: =F31 | H31: =G31 | I31: =H31
A32: Earnings per share - Basic (Rs) | B32: =B26/B30 | C32: =C26/C30 | D32: =D26/D30 | E32: =E26/E30 | F32: =F26/F30 | G32: =G26/G30 | H32: =H26/H30 | I32: =I26/I30
A33: Earnings per share - Diluted (Rs) | B33: =B26/B31 | C33: =C26/C31 | D33: =D26/D31 | E33: =E26/E31 | F33: =F26/F31 | G33: =G26/G31 | H33: =H26/H31 | I33: =I26/I31
A34: Dividends paid | B34: 13631 | C34: 14692 | D34: 20287 | E34: =E26*Assumptions!E27 | F34: =F26*Assumptions!F27 | G34: =G26*Assumptions!G27 | H34: =H26*Assumptions!H27 | I34: =I26*Assumptions!I27
A36: Common size Income Statement
A37: Particulars | B37: =Assumptions!B5 | C37: =Assumptions!C5 | D37: =Assumptions!D5 | E37: =Assumptions!E5 | F37: =Assumptions!F5 | G37: =Assumptions!G5 | H37: =Assumptions!H5 | I37: =Assumptions!I5
A38: Revenue from Operations | B38: =B7/B$7 | C38: =C7/C$7 | D38: =D7/D$7 | E38: =E7/E$7 | F38: =F7/F$7 | G38: =G7/G$7 | H38: =H7/H$7 | I38: =I7/I$7
A39: Employee benefit expenses | B39: =B8/B$7 | C39: =C8/C$7 | D39: =D8/D$7 | E39: =E8/E$7 | F39: =F8/F$7 | G39: =G8/G$7 | H39: =H8/H$7 | I39: =I8/I$7
A40: Cost of technical sub-contractors | B40: =B9/B$7 | C40: =C9/C$7 | D40: =D9/D$7 | E40: =E9/E$7 | F40: =F9/F$7 | G40: =G9/G$7 | H40: =H9/H$7 | I40: =I9/I$7
A41: Travel expenses | B41: =B10/B$7 | C41: =C10/C$7 | D41: =D10/D$7 | E41: =E10/E$7 | F41: =F10/F$7 | G41: =G10/G$7 | H41: =H10/H$7 | I41: =I10/I$7
A42: Cost of software packages and others | B42: =B11/B$7 | C42: =C11/C$7 | D42: =D11/D$7 | E42: =E11/E$7 | F42: =F11/F$7 | G42: =G11/G$7 | H42: =H11/H$7 | I42: =I11/I$7
A43: Communication expenses | B43: =B12/B$7 | C43: =C12/C$7 | D43: =D12/D$7 | E43: =E12/E$7 | F43: =F12/F$7 | G43: =G12/G$7 | H43: =H12/H$7 | I43: =I12/I$7
...

Sheet Balance Sheet
A1: Infosys Limited
A2: Balance Sheet
A3: (In INR Crores, unless otherwise stated) | Blue = reported / hard-coded input, Black = formula, yellow cells = forecast
A5: Particular | B5: =Assumptions!B5 | C5: =Assumptions!C5 | D5: =Assumptions!D5 | E5: =Assumptions!E5 | F5: =Assumptions!F5 | G5: =Assumptions!G5 | H5: =Assumptions!H5 | I5: =Assumptions!I5
A6: Assets
A8: Cash and Cash Equivalents | B8: 12173 | C8: 14786 | D8: 24455 | E8: =CFS!E38 | F8: =CFS!F38 | G8: =CFS!G38 | H8: =CFS!H38 | I8: =CFS!I38
A9: Current Investments | B9: 6909 | C9: 12915 | D9: 12482 | E9: =D9 | F9: =E9 | G9: =F9 | H9: =G9 | I9: =H9
A10: Trade Receivables | B10: 25424 | C10: 30193 | D10: 31158 | E10: ='Income Statement'!E7/Assumptions!E20 | F10: ='Income Statement'!F7/Assumptions!F20 | G10: ='Income Statement'!G7/Assumptions!G20 | H10: ='Income Statement'!H7/Assumptions!H20 | I10: ='Income Statement'!I7/Assumptions!I20
A11: Loans (current) | B11: 289 | C11: 248 | D11: 249 | E11: =D11 | F11: =E11 | G11: =F11 | H11: =G11 | I11: =H11
A12: Other Financial Assets (current) | B12: 11604 | C12: 12085 | D12: 13840 | E12: ='Income Statement'!E7/Assumptions!E21 | F12: ='Income Statement'!F7/Assumptions!F21 | G12: ='Income Statement'!G7/Assumptions!G21 | H12: ='Income Statement'!H7/Assumptions!H21 | I12: ='Income Statement'!I7/Assumptions!I21
A13: Income Tax Assets (current) | B13: 6 | C13: 6397 | D13: 2975 | E13: =D13 | F13: =E13 | G13: =F13 | H13: =G13 | I13: =H13
A14: Other Current Assets | B14: 14476 | C14: 12808 | D14: 11940 | E14: ='Income Statement'!E7/Assumptions!E22 | F14: ='Income Statement'!F7/Assumptions!F22 | G14: ='Income Statement'!G7/Assumptions!G22 | H14: ='Income Statement'!H7/Assumptions!H22 | I14: ='Income Statement'!I7/Assumptions!I22
A15: Total Current Assets | B15: =SUM(B8:B14) | C15: =SUM(C8:C14) | D15: =SUM(D8:D14) | E15: =SUM(E8:E14) | F15: =SUM(F8:F14) | G15: =SUM(G8:G14) | H15: =SUM(H8:H14) | I15: =SUM(I8:I14)
A17: PPE, Net | B17: 13346 | C17: 12370 | D17: 11778 | E17: =Assumptions!E43 | F17: =Assumptions!F43 | G17: =Assumptions!G43 | H17: =Assumptions!H43 | I17: =Assumptions!I43
A18: Right-of-use Assets | B18: 6882 | C18: 6552 | D18: 6311 | E18: =Assumptions!E49 | F18: =Assumptions!F49 | G18: =Assumptions!G49 | H18: =Assumptions!H49 | I18: =Assumptions!I49
A19: Capital Work-In-Progress | B19: 288 | C19: 293 | D19: 814 | E19: =D19 | F19: =E19 | G19: =F19 | H19: =G19 | I19: =H19
A20: Goodwill | B20: 7248 | C20: 7303 | D20: 10106 | E20: =D20 | F20: =E20 | G20: =F20 | H20: =G20 | I20: =H20
A21: Other Intangible Assets | B21: 1749 | C21: 1397 | D21: 2766 | E21: =Assumptions!E55 | F21: =Assumptions!F55 | G21: =Assumptions!G55 | H21: =Assumptions!H55 | I21: =Assumptions!I55
A22: Long-Term Investments | B22: 12569 | C22: 11708 | D22: 11059 | E22: =D22 | F22: =E22 | G22: =F22 | H22: =G22 | I22: =H22
A23: Long-Term Loans | B23: 39 | C23: 34 | D23: 16 | E23: =D23 | F23: =E23 | G23: =F23 | H23: =G23 | I23: =H23
A24: Other Financial Assets (non-current) | B24: 2798 | C24: 3105 | D24: 3511 | E24: =D24 | F24: =E24 | G24: =F24 | H24: =G24 | I24: =H24
A25: Deferred Tax Assets (Net) | B25: 1245 | C25: 454 | D25: 1108 | E25: =D25 | F25: =E25 | G25: =F25 | H25: =G25 | I25: =H25
A26: Income Tax Assets (non-current) | B26: 6453 | C26: 3045 | D26: 1622 | E26: =D26 | F26: =E26 | G26: =F26 | H26: =G26 | I26: =H26
A27: Other Non Current Assets | B27: 2318 | C27: 2121 | D27: 2713 | E27: =D27 | F27: =E27 | G27: =F27 | H27: =G27 | I27: =H27
A28: Total Non-Current Assets | B28: =SUM(B17:B27) | C28: =SUM(C17:C27) | D28: =SUM(D17:D27) | E28: =SUM(E17:E27) | F28: =SUM(F17:F27) | G28: =SUM(G17:G27) | H28: =SUM(H17:H27) | I28: =SUM(I17:I27)
A30: Total Assets | B30: =B15+B28 | C30: =C15+C28 | D30: =D15+D28 | E30: =E15+E28 | F30: =F15+F28 | G30: =G15+G28 | H30: =H15+H28 | I30: =I15+I28
A32: LIABILITIES & EQUITY
A33: Accounts Payable | B33: 3865 | C33: 3956 | D33: 4164 | E33: ='Income Statement'!E7/Assumptions!E23 | F33: ='Income Statement'!F7/Assumptions!F23 | G33: ='Income Statement'!G7/Assumptions!G23 | H33: ='Income Statement'!H7/Assumptions!H23 | I33: ='Income Statement'!I7/Assumptions!I23
A34: Lease Liabilities (current) | B34: 1242 | C34: 1959 | D34: 2455 | E34: =Assumptions!E65 | F34: =Assumptions!F65 | G34: =Assumptions!G65 | H34: =Assumptions!H65 | I34: =Assumptions!I65
A35: Other Financial Liabilities (current) | B35: 18558 | C35: 16959 | D35: 18138 | E35: ='Income Statement'!E7/Assumptions!E24 | F35: ='Income Statement'!F7/Assumptions!F24 | G35: ='Income Statement'!G7/Assumptions!G24 | H35: ='Income Statement'!H7/Assumptions!H24 | I35: ='Income Statement'!I7/Assumptions!I24
A36: Other Current Liabilities | B36: 10830 | C36: 10539 | D36: 11765 | E36: ='Income Statement'!E7/Assumptions!E25 | F36: ='Income Statement'!F7/Assumptions!F25 | G36: ='Income Statement'!G7/Assumptions!G25 | H36: ='Income Statement'!H7/Assumptions!H25 | I36: ='Income Statement'!I7/Assumptions!I25
A37: Provisions | B37: 1307 | C37: 1796 | D37: 1475 | E37: ='Income Statement'!E7/Assumptions!E26 | F37: ='Income Statement'!F7/Assumptions!F26 | G37: ='Income Statement'!G7/Assumptions!G26 | H37: ='Income Statement'!H7/Assumptions!H26 | I37: ='Income Statement'!I7/Assumptions!I26
A38: Income Tax Liabilities (net) | B38: 3384 | C38: 3585 | D38: 4853 | E38: =D38 | F38: =E38 | G38: =F38 | H38: =G38 | I38: =H38
A39: Total Current Liabilities | B39: =SUM(B33:B38) | C39: =SUM(C33:C38) | D39: =SUM(D33:D38) | E39: =SUM(E33:E38) | F39: =SUM(F33:F38) | G39: =SUM(G33:G38) | H39: =SUM(H33:H38) | I39: =SUM(I33:I38)
A41: Lease Liabilities (non-current) | B41: 7057 | C41: 6400 | D41: 5772 | E41: =Assumptions!E66 | F41: =Assumptions!F66 | G41: =Assumptions!G66 | H41: =Assumptions!H66 | I41: =Assumptions!I66
A42: Other Financial Liabilities (non-current) | B42: 2058 | C42: 2130 | D42: 2141 | E42: =D42 | F42: =E42 | G42: =F42 | H42: =G42 | I42: =H42
A43: Deferred Tax Liabilities (Net) | B43: 1220 | C43: 1794 | D43: 1722 | E43: =D43 | F43: =E43 | G43: =F43 | H43: =G43 | I43: =H43
A44: Other Non-Current Liabilities | B44: 500 | C44: 235 | D44: 215 | E44: =D44 | F44: =E44 | G44: =F44 | H44: =G44 | I44: =H44
A45: Total Non-Current Liabilities | B45: =SUM(B41:B44) | C45: =SUM(C41:C44) | D45: =SUM(D41:D44) | E45: =SUM(E41:E44) | F45: =SUM(F41:F44) | G45: =SUM(G41:G44) | H45: =SUM(H41:H44) | I45: =SUM(I41:I44)
A46: Total Liabilities | B46: =B39+B45 | C46: =C39+C45 | D46: =D39+D45 | E46: =E39+E45 | F46: =F39+F45 | G46: =G39+G45 | H46: =H39+H45 | I46: =I39+I45
...

Sheet CFS
A1: Infosys Limited
A2: Cash Flow Statement
A3: (In INR Crores, unless otherwise stated) | Blue = reported / hard-coded input, Black = formula, yellow cells = forecast
A5: Particular | B5: =Assumptions!B5 | C5: =Assumptions!C5 | D5: =Assumptions!D5 | E5: =Assumptions!E5 | F5: =Assumptions!F5 | G5: =Assumptions!G5 | H5: =Assumptions!H5 | I5: =Assumptions!I5
A6: Cash Flows From Operating Activities:
A7: Profit Before Tax | B7: 33322 | C7: 35988 | D7: 37608 | E7: ='Income Statement'!E21 | F7: ='Income Statement'!F21 | G7: ='Income Statement'!G21 | H7: ='Income Statement'!H21 | I7: ='Income Statement'!I21
A8: Depreciation & Amortization | B8: 4225 | C8: 4678 | D8: 4812 | E8: ='Income Statement'!E17 | F8: ='Income Statement'!F17 | G8: ='Income Statement'!G17 | H8: ='Income Statement'!H17 | I8: ='Income Statement'!I17
A9: Interest and Dividend Income (shown in investing) | B9: -1817 | C9: -2067 | D9: -2570 | E9: =-'Income Statement'!E19 | F9: =-'Income Statement'!F19 | G9: =-'Income Statement'!G19 | H9: =-'Income Statement'!H19 | I9: =-'Income Statement'!I19
A10: Finance Cost (paid within lease payments) | B10: 284 | C10: 470 | D10: 416 | E10: ='Income Statement'!E20 | F10: ='Income Statement'!F20 | G10: ='Income Statement'!G20 | H10: ='Income Statement'!H20 | I10: ='Income Statement'!I20
A11: Stock Compensation Expense | B11: 519 | C11: 652 | D11: 802 | E11: 0 | F11: 0 | G11: 0 | H11: 0 | I11: 0 | K11: Not added back in forecast: treated as a cash-like cost
A12: Other Adjustments (ECL, FX, tax-refund interest, other) | B12: 1072 | C12: -198 | D12: 523 | E12: 0 | F12: 0 | G12: 0 | H12: 0 | I12: 0
A13: (Increase) / Decrease in Trade Receivables | B13: -7076 | C13: -2667 | D13: -1769 | E13: ='Balance Sheet'!D10-'Balance Sheet'!E10 | F13: ='Balance Sheet'!E10-'Balance Sheet'!F10 | G13: ='Balance Sheet'!F10-'Balance Sheet'!G10 | H13: ='Balance Sheet'!G10-'Balance Sheet'!H10 | I13: ='Balance Sheet'!H10-'Balance Sheet'!I10
A14: Other Current And Non-Current Assets | B14: -3108 | C14: -1172 | D14: -1024 | E14: =('Balance Sheet'!D12+'Balance Sheet'!D14)-('Balance Sheet'!E12+'Balance Sheet'!E14) | F14: =('Balance Sheet'!E12+'Balance Sheet'!E14)-('Balance Sheet'!F12+'Balance Sheet'!F14) | G14: =('Balance Sheet'!F12+'Balance Sheet'!F14)-('Balance Sheet'!G12+'Balance Sheet'!G14) | H14: =('Balance Sheet'!G12+'Balance Sheet'!G14)-('Balance Sheet'!H12+'Balance Sheet'!H14) | I14: =('Balance Sheet'!H12+'Balance Sheet'!H14)-('Balance Sheet'!I12+'Balance Sheet'!I14)
A15: Trade Payables | B15: -279 | C15: 91 | D15: 176 | E15: ='Balance Sheet'!E33-'Balance Sheet'!D33 | F15: ='Balance Sheet'!F33-'Balance Sheet'!E33 | G15: ='Balance Sheet'!G33-'Balance Sheet'!F33 | H15: ='Balance Sheet'!H33-'Balance Sheet'!G33 | I15: ='Balance Sheet'!I33-'Balance Sheet'!H33
A16: Other Liabilities and Provisions | B16: 4119 | C16: -1334 | D16: 2322 | E16: =('Balance Sheet'!E35+'Balance Sheet'!E36+'Balance Sheet'!E37)-('Balance Sheet'!D35+'Balance Sheet'!D36+'Balance Sheet'!D37) | F16: =('Balance Sheet'!F35+'Balance Sheet'!F36+'Balance Sheet'!F37)-('Balance Sheet'!E35+'Balance Sheet'!E36+'Balance Sheet'!E37) | G16: =('Balance Sheet'!G35+'Balance Sheet'!G36+'Balance Sheet'!G37)-('Balance Sheet'!F35+'Balance Sheet'!F36+'Balance Sheet'!F37) | H16: =('Balance Sheet'!H35+'Balance Sheet'!H36+'Balance Sheet'!H37)-('Balance Sheet'!G35+'Balance Sheet'!G36+'Balance Sheet'!G37) | I16: =('Balance Sheet'!I35+'Balance Sheet'!I36+'Balance Sheet'!I37)-('Balance Sheet'!H35+'Balance Sheet'!H36+'Balance Sheet'!H37)
A17: Cash Generated From Operations | B17: =SUM(B7:B16) | C17: =SUM(C7:C16) | D17: =SUM(D7:D16) | E17: =SUM(E7:E16) | F17: =SUM(F7:F16) | G17: =SUM(G7:G16) | H17: =SUM(H7:H16) | I17: =SUM(I7:I16)
A18: Income Taxes Paid (Net) | B18: -8794 | C18: -9231 | D18: -5602 | E18: =-('Income Statement'!E22+'Income Statement'!E23) | F18: =-('Income Statement'!F22+'Income Statement'!F23) | G18: =-('Income Statement'!G22+'Income Statement'!G23) | H18: =-('Income Statement'!H22+'Income Statement'!H23) | I18: =-('Income Statement'!I22+'Income Statement'!I23)
A19: Net Cash Flow From Operating Activities | B19: =B17+B18 | C19: =C17+C18 | D19: =D17+D18 | E19: =E17+E18 | F19: =F17+F18 | G19: =G17+G18 | H19: =H17+H18 | I19: =I17+I18
A21: Cash Flows From Investing Activities:
A22: Payments For Fixed Assets (Capex) | B22: -2579 | C22: -2201 | D22: -2237 | E22: =-(Assumptions!E41+Assumptions!E53) | F22: =-(Assumptions!F41+Assumptions!F53) | G22: =-(Assumptions!G41+Assumptions!G53) | H22: =-(Assumptions!H41+Assumptions!H53) | I22: =-(Assumptions!I41+Assumptions!I53)
A23: Interest and Dividend Received | B23: 1525 | C23: 1768 | D23: 2040 | E23: ='Income Statement'!E19 | F23: ='Income Statement'!F19 | G23: ='Income Statement'!G19 | H23: ='Income Statement'!H19 | I23: ='Income Statement'!I19
A24: Acquisition of Business (incl. contingent consideration) | B24: -970 | C24: -101 | D24: -3155 | E24: 0 | F24: 0 | G24: 0 | H24: 0 | I24: 0
A25: Net Purchase/Sale of Investments, Deposits and Other | B25: 815 | C25: -4475 | D25: 1406 | E25: 0 | F25: 0 | G25: 0 | H25: 0 | I25: 0 | K25: Investments held flat in forecast; surplus builds up as cash
A26: Net Cash Flow From Investing Activities | B26: =SUM(B22:B25) | C26: =SUM(C22:C25) | D26: =SUM(D22:D25) | E26: =SUM(E22:E25) | F26: =SUM(F22:F25) | G26: =SUM(G22:G25) | H26: =SUM(H22:H25) | I26: =SUM(I22:I25)
A28: Cash Flows From Financing Activities:
A29: Payment of Lease Liabilities (principal + interest) | B29: -1231 | C29: -2024 | D29: -2355 | E29: =-Assumptions!E63 | F29: =-Assumptions!F63 | G29: =-Assumptions!G63 | H29: =-Assumptions!H63 | I29: =-Assumptions!I63
A30: Dividend Paid | B30: -13631 | C30: -14692 | D30: -20287 | E30: =-'Income Statement'!E34 | F30: =-'Income Statement'!F34 | G30: =-'Income Statement'!G34 | H30: =-'Income Statement'!H34 | I30: =-'Income Statement'!I34
A31: Buyback of Equity Shares | B31: -11499 | C31: 0 | D31: 0 | E31: 0 | F31: 0 | G31: 0 | H31: 0 | I31: 0
A32: Other Financing Activity (NCI dividend, options, loan repayment, other) | B32: -334 | C32: -788 | D32: -1519 | E32: 0 | F32: 0 | G32: 0 | H32: 0 | I32: 0
A33: Net Cash Used In Financing Activities | B33: =SUM(B29:B32) | C33: =SUM(C29:C32) | D33: =SUM(D29:D32) | E33: =SUM(E29:E32) | F33: =SUM(F29:F32) | G33: =SUM(G29:G32) | H33: =SUM(H29:H32) | I33: =SUM(I29:I32)
A35: Increase (Decrease) In Cash And Cash Equivalents | B35: =B19+B26+B33 | C35: =C19+C26+C33 | D35: =D19+D26+D33 | E35: =E19+E26+E33 | F35: =F19+F26+F33 | G35: =G19+G26+G33 | H35: =H19+H26+H33 | I35: =I19+I26+I33
A36: Effect Of Exchange Rate Change On Cash | B36: 138 | C36: -84 | D36: 82 | E36: 0 | F36: 0 | G36: 0 | H36: 0 | I36: 0
A37: Cash And Cash Equivalents At Beginning Of Period | B37: 17472 | C37: 12173 | D37: 14786 | E37: =D38 | F37: =E38 | G37: =F38 | H37: =G38 | I37: =H38
A38: Cash And Cash Equivalents At The End Of Period | B38: =B35+B36+B37 | C38: =C35+C36+C37 | D38: =D35+D36+D37 | E38: =E35+E36+E37 | F38: =F35+F36+F37 | G38: =G35+G36+G37 | H38: =H35+H36+H37 | I38: =I35+I36+I37
A39: Check vs Balance Sheet cash -> should be 0 | B39: =ROUND(B38-'Balance Sheet'!B8,0) | C39: =ROUND(C38-'Balance Sheet'!C8,0) | D39: =ROUND(D38-'Balance Sheet'!D8,0) | E39: =ROUND(E38-'Balance Sheet'!E8,0) | F39: =ROUND(F38-'Balance Sheet'!F8,0) | G39: =ROUND(G38-'Balance Sheet'!G8,0) | H39: =ROUND(H38-'Balance Sheet'!H8,0) | I39: =ROUND(I38-'Balance Sheet'!I8,0)
A41: Free Cash Flow (Operating cash flow - Capex) | B41: =B19+B22 | C41: =C19+C22 | D41: =D19+D22 | E41: =E19+E22 | F41: =F19+F22 | G41: =G19+G22 | H41: =H19+H22 | I41: =I19+I22

Sheet Valuation
A1: Infosys Limited
A2: Valuation - Discounted Cash Flow (DCF)
A3: (In INR Crores, unless otherwise stated) | Blue = reported / hard-coded input, Black = formula, yellow cells = forecast
A5: Long Term Growth Rate | B5: 0.055 | C5: Input: ~4% US$ growth + ~1.5% INR depreciation
A7: Cost of Equity (Ke) | B7: =E7+(B8*E9) | D7: Risk Free rate | E7: 0.0681 | F7: 10-yr G-sec yield, 31-Mar-2025
A8: Stock Beta | B8: 0.9 | D8: Market Return | E8: 0.1231
A9: Long Term Cost of Debt (lease interest) | B9: ='Income Statement'!D20/('Balance Sheet'!C34+'Balance Sheet'!C41) | D9: Market Premium | E9: =E8-E7
A10: Tax Rate | B10: =Assumptions!D15 | D10: Weight of Equity | E10: =E12/(E12+E13)
A11: WACC | B11: =(E10*B7)+(E11*B9*(1-B10)) | D11: Weight of Debt | E11: =E13/(E12+E13)
D12: Equity (market capitalisation) | E12: =B15
A13: Number of Shares Outstanding (crore, diluted) | B13: ='Income Statement'!D31 | D13: Total Debt (lease liabilities) | E13: ='Balance Sheet'!D34+'Balance Sheet'!D41
A14: Current Market Price (Rs) | B14: 1573.4 | C14: Company-reported market cap Rs6,52,332 crore / 414.6 crore shares at 31-Mar-2025
A15: Market Capitalisation | B15: =B13*B14
A16: Debt (borrowings) | B16: 0 | C16: Infosys has no borrowings; leases are treated as operating costs in FCFF (see row 34), so they are not counted as debt here
A17: Cash and Investments | B17: ='Balance Sheet'!D8+'Balance Sheet'!D9+'Balance Sheet'!D22
A18: Minority Interest | B18: ='Balance Sheet'!D52
A19: Enterprise Value (market) | B19: =B15+B16-B17+B18
A21: CALCULATION OF FREE CASH FLOW TO FIRM (FCFF)
A22: Particulars | B22: =Assumptions!B5 | C22: =Assumptions!C5 | D22: =Assumptions!D5 | E22: =Assumptions!E5 | F22: =Assumptions!F5 | G22: =Assumptions!G5 | H22: =Assumptions!H5 | I22: =Assumptions!I5 | J22: Terminal Value
A23: Revenues | B23: ='Income Statement'!B7 | C23: ='Income Statement'!C7 | D23: ='Income Statement'!D7 | E23: ='Income Statement'!E7 | F23: ='Income Statement'!F7 | G23: ='Income Statement'!G7 | H23: ='Income Statement'!H7 | I23: ='Income Statement'!I7
A24: % Growth Revenue | C24: =C23/B23-1 | D24: =D23/C23-1 | E24: =E23/D23-1 | F24: =F23/E23-1 | G24: =G23/F23-1 | H24: =H23/G23-1 | I24: =I23/H23-1
A25: EBITDA | B25: ='Income Statement'!B16 | C25: ='Income Statement'!C16 | D25: ='Income Statement'!D16 | E25: ='Income Statement'!E16 | F25: ='Income Statement'!F16 | G25: ='Income Statement'!G16 | H25: ='Income Statement'!H16 | I25: ='Income Statement'!I16
A26: EBIT | B26: ='Income Statement'!B18 | C26: ='Income Statement'!C18 | D26: ='Income Statement'!D18 | E26: ='Income Statement'!E18 | F26: ='Income Statement'!F18 | G26: ='Income Statement'!G18 | H26: ='Income Statement'!H18 | I26: ='Income Statement'!I18
A27: Tax Rate | B27: =('Income Statement'!B22+'Income Statement'!B23)/'Income Statement'!B21 | C27: =('Income Statement'!C22+'Income Statement'!C23)/'Income Statement'!C21 | D27: =('Income Statement'!D22+'Income Statement'!D23)/'Income Statement'!D21 | E27: =('Income Statement'!E22+'Income Statement'!E23)/'Income Statement'!E21 | F27: =('Income Statement'!F22+'Income Statement'!F23)/'Income Statement'!F21 | G27: =('Income Statement'!G22+'Income Statement'!G23)/'Income Statement'!G21 | H27: =('Income Statement'!H22+'Income Statement'!H23)/'Income Statement'!H21 | I27: =('Income Statement'!I22+'Income Statement'!I23)/'Income Statement'!I21
A28: Net Operating Profit After Taxes (NOPAT = EBIT x (1 - tax)) | B28: =B26*(1-B27) | C28: =C26*(1-C27) | D28: =D26*(1-D27) | E28: =E26*(1-E27) | F28: =F26*(1-F27) | G28: =G26*(1-G27) | H28: =H26*(1-H27) | I28: =I26*(1-I27)
A29: + Depreciation & Amortisation | B29: ='Income Statement'!B17 | C29: ='Income Statement'!C17 | D29: ='Income Statement'!D17 | E29: ='Income Statement'!E17 | F29: ='Income Statement'!F17 | G29: ='Income Statement'!G17 | H29: ='Income Statement'!H17 | I29: ='Income Statement'!I17
A30: - Capex | B30: =CFS!B22 | C30: =CFS!C22 | D30: =CFS!D22 | E30: =CFS!E22 | F30: =CFS!F22 | G30: =CFS!G22 | H30: =CFS!H22 | I30: =CFS!I22
A31: +/- Change in Working Capital | B31: =SUM(CFS!B13:B16) | C31: =SUM(CFS!C13:C16) | D31: =SUM(CFS!D13:D16) | E31: =SUM(CFS!E13:E16) | F31: =SUM(CFS!F13:F16) | G31: =SUM(CFS!G13:G16) | H31: =SUM(CFS!H13:H16) | I31: =SUM(CFS!I13:I16)
A32: - Lease payments (principal + interest) | B32: =CFS!B29 | C32: =CFS!C29 | D32: =CFS!D29 | E32: =CFS!E29 | F32: =CFS!F29 | G32: =CFS!G29 | H32: =CFS!H29 | I32: =CFS!I29 | K32: Leases treated as an operating cost
A33: FCFF | B33: =B28+B29+B30+B31+B32 | C33: =C28+C29+C30+C31+C32 | D33: =D28+D29+D30+D31+D32 | E33: =E28+E29+E30+E31+E32 | F33: =F28+F29+F30+F31+F32 | G33: =G28+G29+G30+G31+G32 | H33: =H28+H29+H30+H31+H32 | I33: =I28+I29+I30+I31+I32 | J33: =I33*(1+B5)/(B11-B5)
A34: Years to Discount | E34: 1 | F34: 2 | G34: 3 | H34: 4 | I34: 5 | J34: =I34
A35: Discount Factor = 1 / (1 + WACC) ^ years | E35: =1/((1+$B$11)^E34) | F35: =1/((1+$B$11)^F34) | G35: =1/((1+$B$11)^G34) | H35: =1/((1+$B$11)^H34) | I35: =1/((1+$B$11)^I34) | J35: =I35
A36: PV of FCFF | E36: =E33*E35 | F36: =F33*F35 | G36: =G33*G35 | H36: =H33*H35 | I36: =I33*I35 | J36: =J33*J35
A39: Sum of PV of FCFF (FY2026E - FY2030E) | B39: =SUM(E36:I36)
A40: Terminal Value = FCFF5 x (1 + g) / (WACC - g) | B40: =J33
A41: Present Value of Terminal Value | B41: =J36
A42: Company's Enterprise Value (EV) | B42: =B39+B41
A43: + Cash and Investments | B43: =B17
A44: - Debt (borrowings) | B44: =B16
A45: - Minority Interest | B45: =B18
...
